Workbook

Sheet 一晒过后删除片段见重复值
A1: 0 | B1: 注释 | C1: target | D1: 匹配度分数 | E1: 1 | F1: RT | G1: 2 | H1: 3 | I1: 4 | J1: 5 | K1: 6 | L1: 7 | M1: 8
A2: 9 | B2: CAEP(d14:2/12:3) | C2: 525.3441 | D2: 0.88 | E2: CAEP(d26:5) | F2: 3.418 | G2: 15024 | H2: [507.3351, 126.0333, 242.2071, 489.3279, 224.1987, 206.1879, 400.3121] | I2: [886.3094, 413.6825, 330.3465, 305.1225, 290.0363, 265.9185, 173.0513] | J2: ['CAEP(d26:5)-1H2O', '[C2H8NO3P+H]+', 'd14:2+2OH', 'CAEP(d26:5)-2H2O', 'd14:2+OH', 'd14:2', 'CAEP(d26:5)-C2H8NO3P'] | K2: 2664.467 | L2: 88 | M2: 1 | N2: #N/A
A3: 16 | B3: CAEP(d14:3/15:0) | C3: 571.4273 | D3: 0.62 | E3: CAEP(d29:3) | F3: 5.283 | G3: 264846 | H3: [553.4244, 222.1835, 204.1763, 535.4133, 240.1936] | I3: [180.0, 145.1635, 116.8929, 81.7788, 64.1607] | J3: ['CAEP(d29:3)-1H2O', 'd14:3+OH', 'd14:3', 'CAEP(d29:3)-2H2O', 'd14:3+2OH'] | K3: 587.9959 | L3: 62 | M3: 1 | N3: #N/A
A4: 37 | B4: CAEP(d14:3/21:3)(2OH) | C4: 665.4654 | D4: 0.75 | E4: CAEP(d35:6)(2OH) | F4: 12.46 | G4: 12180 | H4: [647.4542, 647.4542, 540.4346, 540.4346, 629.4525, 629.4525] | I4: [41.2404, 41.2404, 37.0833, 37.0833, 21.25, 21.25] | J4: ['CAEP(d35:6)(2OH)-1H2O', 'CAEP(d35:6)(2OH)-1H2O', 'CAEP(d35:6)(2OH)-C2H8NO3P', 'CAEP(d35:6)(2OH)-C2H8NO3P', 'CAEP(d35:6)(2OH)-2H2O', 'CAEP(d35:6)(2OH)-2H2O'] | K4: 199.1474 | L4: 75 | M4: 1 | N4: #N/A
A5: 56 | B5: CAEP(d14:3/21:4) | C5: 647.4587 | D5: 0.5 | E5: CAEP(d35:7) | F5: 11.478 | G5: 135914 | H5: [240.1927, 629.4434, 204.1709, 222.1838] | I5: [308.0312, 196.3472, 59.0, 44.0833] | J5: ['d14:3+2OH', 'CAEP(d35:7)-1H2O', 'd14:3', 'd14:3+OH'] | K5: 607.4617 | L5: 40 | M5: 0.59 | N5: #N/A
A6: 97 | B6: CAEP(d14:3/25:4) | C6: 703.5164 | D6: 0.5 | E6: CAEP(d39:7) | F6: 6.942 | G6: 159861 | H6: [685.4972, 204.1732, 240.1965, 667.4903] | I6: [540.1639, 237.2426, 170.4133, 86.125] | J6: ['CAEP(d39:7)-1H2O', 'd14:3', 'd14:3+2OH', 'CAEP(d39:7)-2H2O'] | K6: 1033.9448 | L6: 50 | M6: 1 | N6: #N/A
A7: 10 | B7: CAEP(d14:4/12:1) | C7: 525.3441 | D7: 0.88 | E7: CAEP(d26:5) | F7: 3.418 | G7: 15024 | H7: [507.3351, 126.0333, 202.1594, 489.3279, 220.1698, 238.1808, 400.3121] | I7: [886.3094, 413.6825, 325.0994, 305.1225, 201.9469, 182.656, 173.0513] | J7: ['CAEP(d26:5)-1H2O', '[C2H8NO3P+H]+', 'd14:4', 'CAEP(d26:5)-2H2O', 'd14:4+OH', 'd14:4+2OH', 'CAEP(d26:5)-C2H8NO3P'] | K7: 2487.868 | L7: 70.4 | M7: 0.93 | N7: #N/A
A8: 192 | B8: CAEP(d14:4/40:2) | C8: 915.7619 | D8: 0.5 | E8: CAEP(d54:6) | F8: 10.782 | G8: 40314 | H8: [897.7521, 897.7521, 220.1712, 202.1607] | I8: [945.3245, 945.3245, 641.8412, 160.625] | J8: ['CAEP(d54:6)-1H2O', 'CAEP(d54:6)-1H2O', 'd14:4+OH', 'd14:4'] | K8: 2693.1152 | L8: 50 | M8: 1 | N8: #N/A
A9: 38 | B9: CAEP(d15:3/20:3)(2OH) | C9: 665.4654 | D9: 0.75 | E9: CAEP(d35:6)(2OH) | F9: 12.46 | G9: 12180 | H9: [647.4542, 647.4542, 540.4346, 540.4346, 629.4525, 629.4525] | I9: [41.2404, 41.2404, 37.0833, 37.0833, 21.25, 21.25] | J9: ['CAEP(d35:6)(2OH)-1H2O', 'CAEP(d35:6)(2OH)-1H2O', 'CAEP(d35:6)(2OH)-C2H8NO3P', 'CAEP(d35:6)(2OH)-C2H8NO3P', 'CAEP(d35:6)(2OH)-2H2O', 'CAEP(d35:6)(2OH)-2H2O'] | K9: 199.1474 | L9: 75 | M9: 1 | N9: #N/A
A10: 54 | B10: CAEP(d15:3/20:4) | C10: 647.4586 | D10: 0.38 | E10: CAEP(d35:7) | F10: 15.038 | G10: 84104 | H10: [218.1885, 254.2107, 236.1996] | I10: [230.4444, 49.0625, 26.25] | J10: ['d15:3', 'd15:3+2OH', 'd15:3+OH'] | K10: 305.7569 | L10: 38 | M10: 1 | N10: #N/A
A11: 39 | B11: CAEP(d15:4/20:2)(2OH) | C11: 665.4654 | D11: 0.75 | E11: CAEP(d35:6)(2OH) | F11: 12.46 | G11: 12180 | H11: [647.4542, 647.4542, 540.4346, 540.4346, 629.4525, 629.4525] | I11: [41.2404, 41.2404, 37.0833, 37.0833, 21.25, 21.25] | J11: ['CAEP(d35:6)(2OH)-1H2O', 'CAEP(d35:6)(2OH)-1H2O', 'CAEP(d35:6)(2OH)-C2H8NO3P', 'CAEP(d35:6)(2OH)-C2H8NO3P', 'CAEP(d35:6)(2OH)-2H2O', 'CAEP(d35:6)(2OH)-2H2O'] | K11: 199.1474 | L11: 75 | M11: 1 | N11: #N/A
A12: 24 | B12: CAEP(d16:3/14:0)(2OH) | C12: 601.4384 | D12: 0.38 | E12: CAEP(d30:3)(2OH) | F12: 4.871 | G12: 22393 | H12: [250.2151, 268.2267, 583.4347] | I12: [1137.0951, 267.2656, 133.5956] | J12: ['d16:3+OH', 'd16:3+2OH', 'CAEP(d30:3)(2OH)-1H2O'] | K12: 1537.9563 | L12: 34.2 | M12: 0.82 | N12: #N/A
A13: 41 | B13: CAEP(d17:2/10:4)(2OH) | C13: 553.342 | D13: 0.62 | E13: CAEP(d27:6)(2OH) | F13: 8.117 | G13: 264846 | H13: [266.246, 248.2363, 284.2605, 535.3257, 517.3156] | I13: [4027.4604, 2861.3145, 668.1827, 72.0, 41.5] | J13: ['d17:2+OH', 'd17:2', 'd17:2+2OH', 'CAEP(d27:6)(2OH)-1H2O', 'CAEP(d27:6)(2OH)-2H2O'] | K13: 7670.4576 | L13: 55.8 | M13: 1 | N13: #N/A
A14: 128 | B14: CAEP(d17:2/35:1)(2OH) | C14: 909.7787 | D14: 0.38 | E14: CAEP(d52:3)(2OH) | F14: 22.072 | G14: 11005 | H14: [266.2522, 284.2551, 784.7514] | I14: [41.25, 34.3472, 20.3472] | J14: ['d17:2+OH', 'd17:2+2OH', 'CAEP(d52:3)(2OH)-C2H8NO3P'] | K14: 95.9444 | L14: 38 | M14: 1 | N14: #N/A
A15: 195 | B15: CAEP(d17:3/37:3) | C15: 915.762 | D15: 0.62 | E15: CAEP(d54:6) | F15: 10.07 | G15: 36199 | H15: [897.7521, 897.7521, 282.2476, 246.2264, 264.2364] | I15: [945.3245, 945.3245, 376.6039, 255.3672, 177.1157] | J15: ['CAEP(d54:6)-1H2O', 'CAEP(d54:6)-1H2O', 'd17:3+2OH', 'd17:3', 'd17:3+OH'] | K15: 2699.7358 | L15: 62 | M15: 1 | N15: CAEP(d17:3/37:3)
A16: 137 | B16: CAEP(d17:4/35:0) | C16: 891.7643 | D16: 0.62 | E16: CAEP(d52:4) | F16: 10.382 | G16: 76311 | H16: [873.7499, 244.2104, 280.2322, 855.7521, 262.2188] | I16: [802.5878, 357.2112, 201.125, 114.5, 60.3333] | J16: ['CAEP(d52:4)-1H2O', 'd17:4', 'd17:4+2OH', 'CAEP(d52:4)-2H2O', 'd17:4+OH'] | K16: 1535.7573 | L16: 62 | M16: 1 | N16: #N/A
A17: 33 | B17: CAEP(d18:1/10:2) | C17: 557.4118 | D17: 0.5 | E17: CAEP(d28:3) | F17: 4.882 | G17: 68297 | H17: [282.2788, 521.3845, 539.4088, 300.285] | I17: [259.1607, 72.0, 46.9055, 40.0625] | J17: ['d18:1+OH', 'CAEP(d28:3)-2H2O', 'CAEP(d28:3)-1H2O', 'd18:1+2OH'] | K17: 418.1287 | L17: 40 | M17: 0.72 | N17: #N/A
A18: 42 | B18: CAEP(d18:1/18:4) | C18: 665.502 | D18: 0.38 | E18: CAEP(d36:5) | F18: 11.964 | G18: 84104 | H18: [300.2885, 282.2781, 629.4778] | I18: [436.3471, 245.125, 142.0833] | J18: ['d18:1+2OH', 'd18:1+OH', 'CAEP(d36:5)-2H2O'] | K18: 823.5554 | L18: 38 | M18: 1 | N18: #N/A
A19: 86 | B19: CAEP(d18:1/33:0)(2OH) | C19: 899.7929 | D19: 0.38 | E19: CAEP(d51:1)(2OH) | F19: 15.897 | G19: 52108 | H19: [264.2691, 881.7793, 282.2756] | I19: [71.0081, 57.0, 47.3472] | J19: ['d18:1', 'CAEP(d51:1)(2OH)-1H2O', 'd18:1+OH'] | K19: 175.3553 | L19: 38 | M19: 1 | N19: #N/A
A20: 159 | B20: CAEP(d18:1/34:2) | C20: 893.7804 | D20: 0.62 | E20: CAEP(d52:3) | F20: 10.777 | G20: 9611 | H20: [875.7671, 857.7467, 264.2695, 282.2847, 300.2849] | I20: [1266.6459, 283.2, 173.5048, 162.4448, 20.875] | J20: ['CAEP(d52:3)-1H2O', 'CAEP(d52:3)-2H2O', 'd18:1', 'd18:1+OH', 'd18:1+2OH'] | K20: 1906.6705 | L20: 55.8 | M20: 0.98 | N20: #N/A
A21: 186 | B21: CAEP(d18:1/34:3)(2OH) | C21: 907.7633 | D21: 0.5 | E21: CAEP(d52:4)(2OH) | F21: 16.511 | G21: 52108 | H21: [264.2678, 282.275, 889.761, 300.2859] | I21: [181.4083, 95.45, 27.0, 27.0] | J21: ['d18:1', 'd18:1+OH', 'CAEP(d52:4)(2OH)-1H2O', 'd18:1+2OH'] | K21: 330.8583 | L21: 45 | M21: 0.49 | N21: #N/A
A22: 185 | B22: CAEP(d18:1/34:4)(2OH) | C22: 905.7477 | D22: 0.38 | E22: CAEP(d52:5)(2OH) | F22: 15.565 | G22: 16298 | H22: [264.2703, 282.275, 869.7192] | I22: [295.2268, 100.1023, 21.1607] | J22: ['d18:1', 'd18:1+OH', 'CAEP(d52:5)(2OH)-2H2O'] | K22: 416.4898 | L22: 38 | M22: 1 | N22: #N/A
A23: 75 | B23: CAEP(d18:1/36:4) | C23: 917.7802 | D23: 0.38 | E23: CAEP(d54:5) | F23: 14.725 | G23: 418864 | H23: [282.2784, 264.2705, 881.7451] | I23: [254.2667, 98.875, 94.5] | J23: ['d18:1+OH', 'd18:1', 'CAEP(d54:5)-2H2O'] | K23: 447.6417 | L23: 38 | M23: 1 | N23: #N/A
A24: 86 | B24: CAEP(d18:2/28:1)(2OH) | C24: 825.6838 | D24: 0.38 | E24: CAEP(d46:3)(2OH) | F24: 5.283 | G24: 264846 | H24: [298.2769, 807.6739, 280.2647] | I24: [286.05, 105.0, 92.654] | J24: ['d18:2+2OH', 'CAEP(d46:3)(2OH)-1H2O', 'd18:2+OH'] | K24: 483.704 | L24: 30.4 | M24: 0.62 | N24: #N/A
A25: 62 | B25: CAEP(d18:2/29:4) | C25: 817.6584 | D25: 0.5 | E25: CAEP(d47:6) | F25: 6.797 | G25: 293044 | H25: [262.2538, 280.262, 799.6517, 298.2758] | I25: [876.0143, 683.3461, 291.0153, 228.9698] | J25: ['d18:2', 'd18:2+OH', 'CAEP(d47:6)-1H2O', 'd18:2+2OH'] | K25: 2079.3455 | L25: 50 | M25: 1 | N25: #N/A
A26: 98 | B26: CAEP(d18:2/31:4) | C26: 845.6922 | D26: 0.75 | E26: CAEP(d49:6) | F26: 8.107 | G26: 87720 | H26: [262.2529, 280.2629, 298.273, 827.6862, 809.6561, 126.033] | I26: [5571.6616, 5181.4727, 2351.7107, 502.4498, 102.5568, 20.0] | J26: ['d18:2', 'd18:2+OH', 'd18:2+2OH', 'CAEP(d49:6)-1H2O', 'CAEP(d49:6)-2H2O', '[C2H8NO3P+H]+'] | K26: 13729.852 | L26: 75 | M26: 1 | N26: #N/A
A27: 168 | B27: CAEP(d18:3/34:4) | C27: 885.723 | D27: 0.5 | E27: CAEP(d52:7) | F27: 13.257 | G27: 180258 | H27: [278.2468, 296.258, 760.6964, 867.7235] | I27: [398.9698, 198.225, 160.3472, 124.3603] | J27: ['d18:3+OH', 'd18:3+2OH', 'CAEP(d52:7)-C2H8NO3P', 'CAEP(d52:7)-1H2O'] | K27: 881.9023 | L27: 50 | M27: 1 | N27: #N/A
... A49: 20 | B49: Cer(d14:0/17:4) | C49: 490.4254 | D49: 0.5 | E49: Cer(d31:4) | F49: 8.839 | G49: 538642 | H49: [228.2345, 210.2185, 472.4191] | I49: [204.3214, 136.8178, 107.0833] | J49: ['d14:0+OH', 'd14:0', 'Cer(d31:4)-1H2O'] | K49: 448.2225 | L49: 50 | M49: 1 | N49: #N/A
A50: 27 | B50: Cer(d14:0/18:0) | C50: 512.5034 | D50: 0.83 | E50: Cer(d32:0) | F50: 7.343 | G50: 8218 | H50: [494.4922, 228.2321, 210.2209, 246.2439, 476.48] | I50: [11305.5947, 4294.0005, 2972.4082, 1127.3517, 606.7742] | J50: ['Cer(d32:0)-1H2O', 'd14:0+OH', 'd14:0', 'd14:0+2OH', 'Cer(d32:0)-2H2O'] | K50: 20306.129 | L50: 83 | M50: 1 | N50: Cer(d14:0/18:0)
A51: 48 | B51: Cer(d14:0/19:3)(dOH) | C51: 552.463 | D51: 0.83 | E51: Cer(d33:3)(dOH) | F51: 8.072 | G51: 9611 | H51: [246.2389, 210.2203, 228.229, 534.4609, 516.4362] | I51: [38353.3242, 1680.2898, 316.6712, 69.75, 51.0] | J51: ['d14:0+2OH', 'd14:0', 'd14:0+OH', 'Cer(d33:3)(dOH)-1H2O', 'Cer(d33:3)(dOH)-2H2O'] | K51: 40471.035 | L51: 83 | M51: 1 | N51: #N/A
A52: 43 | B52: Cer(d14:0/20:0) | C52: 540.5352 | D52: 0.83 | E52: Cer(d34:0) | F52: 8.205 | G52: 9611 | H52: [522.5239, 228.2321, 210.2216, 246.2429, 504.5135] | I52: [78054.5312, 22827.4648, 10480.3516, 7398.9395, 5926.2861] | J52: ['Cer(d34:0)-1H2O', 'd14:0+OH', 'd14:0', 'd14:0+2OH', 'Cer(d34:0)-2H2O'] | K52: 124687.57 | L52: 83 | M52: 1 | N52: Cer(d14:0/20:0)
A53: 23 | B53: Cer(d14:0/20:0) | C53: 540.537 | D53: 0.83 | E53: Cer(d34:0) | F53: 12.681 | G53: 135914 | H53: [522.5233, 228.2315, 210.2209, 246.2429, 504.5137] | I53: [18996.668, 3852.9404, 2629.9849, 2429.0127, 1796.4441] | J53: ['Cer(d34:0)-1H2O', 'd14:0+OH', 'd14:0', 'd14:0+2OH', 'Cer(d34:0)-2H2O'] | K53: 29705.05 | L53: 83 | M53: 1 | N53: Cer(d14:0/20:0)
A54: 42 | B54: Cer(d14:0/21:4)(dOH) | C54: 578.4799 | D54: 0.67 | E54: Cer(d35:4)(dOH) | F54: 8.166 | G54: 9611 | H54: [246.2391, 210.2229, 542.4605, 228.2301] | I54: [57046.3047, 265.0046, 137.4, 117.5089] | J54: ['d14:0+2OH', 'd14:0', 'Cer(d35:4)(dOH)-2H2O', 'd14:0+OH'] | K54: 57566.218 | L54: 67 | M54: 1 | N54: #N/A
A55: 31 | B55: Cer(d14:0/22:0) | C55: 568.5662 | D55: 0.83 | E55: Cer(d36:0) | F55: 9.073 | G55: 135914 | H55: [550.5542, 228.2313, 210.221, 246.2416, 532.5426] | I55: [126174.2109, 34375.543, 21641.6777, 12911.3154, 5821.8608] | J55: ['Cer(d36:0)-1H2O', 'd14:0+OH', 'd14:0', 'd14:0+2OH', 'Cer(d36:0)-2H2O'] | K55: 200924.61 | L55: 83 | M55: 1 | N55: Cer(d14:0/22:0)
A56: 45 | B56: Cer(d14:0/23:0) | C56: 582.5824 | D56: 0.83 | E56: Cer(d37:0) | F56: 9.524 | G56: 54725 | H56: [564.5693, 228.2316, 210.2221, 246.2407, 546.5577] | I56: [16977.707, 3920.9167, 2178.8452, 1274.4218, 1157.8484] | J56: ['Cer(d37:0)-1H2O', 'd14:0+OH', 'd14:0', 'd14:0+2OH', 'Cer(d37:0)-2H2O'] | K56: 25509.739 | L56: 83 | M56: 1 | N56: Cer(d14:0/23:0)
A57: 44 | B57: Cer(d14:0/23:0)(dOH) | C57: 614.5708 | D57: 0.5 | E57: Cer(d37:0)(dOH) | F57: 12.419 | G57: 10209 | H57: [210.2221, 246.2395, 596.5572] | I57: [162.75, 86.2893, 49.4444] | J57: ['d14:0', 'd14:0+2OH', 'Cer(d37:0)(dOH)-1H2O'] | K57: 298.4837 | L57: 50 | M57: 1 | N57: #N/A
A58: 59 | B58: Cer(d14:0/23:4)(dOH) | C58: 606.5053 | D58: 0.67 | E58: Cer(d37:4)(dOH) | F58: 10.743 | G58: 9611 | H58: [246.2395, 588.5023, 570.4924, 228.2324] | I58: [3788.1707, 140.1875, 37.125, 34.1607] | J58: ['d14:0+2OH', 'Cer(d37:4)(dOH)-1H2O', 'Cer(d37:4)(dOH)-2H2O', 'd14:0+OH'] | K58: 3999.6439 | L58: 67 | M58: 1 | N58: #N/A
A59: 98 | B59: Cer(d14:0/25:0)(dOH) | C59: 642.6027 | D59: 0.67 | E59: Cer(d39:0)(dOH) | F59: 8.01 | G59: 293044 | H59: [210.2218, 246.2398, 624.5841, 228.2321] | I59: [303.4706, 100.4083, 62.3472, 20.025] | J59: ['d14:0', 'd14:0+2OH', 'Cer(d39:0)(dOH)-1H2O', 'd14:0+OH'] | K59: 486.2511 | L59: 67 | M59: 1 | N59: #N/A
A60: 1 | B60: Cer(d14:1/10:0) | C60: 398.3639 | D60: 0.5 | E60: Cer(d24:1) | F60: 9.326 | G60: 139669 | H60: [380.3508, 362.3371, 208.2049] | I60: [550.7348, 195.3611, 169.0] | J60: ['Cer(d24:1)-1H2O', 'Cer(d24:1)-2H2O', 'd14:1'] | K60: 915.0959 | L60: 45 | M60: 0.95 | N60: #N/A
A61: 3 | B61: Cer(d14:1/11:3) | C61: 406.329 | D61: 0.5 | E61: Cer(d25:4) | F61: 19.376 | G61: 52108 | H61: [244.224, 388.3174, 226.2208] | I61: [87.6667, 55.0833, 32.625] | J61: ['d14:1+2OH', 'Cer(d25:4)-1H2O', 'd14:1+OH'] | K61: 175.375 | L61: 45 | M61: 0.64 | N61: #N/A
...

Sheet 原版保留时间规律
A1: Unnamed: 0 | B1: 注释 | C1: target | D1: 匹配度分数 | E1: 母离子 | F1: RT | G1: 实际mz | H1: 强度 | I1: 碎片 | J1: 强度总和 | K1: 总分数 | L1: 相对强度 | M1: series | N1: FA_Carbon | O1: index | P1: 公式列 | Q1: R2列
A2: 5 | B2: CAEP(d17:3/32:3) | C2: 845.6922 | D2: 0.62 | E2: CAEP(d49:6) | F2: 8.107 | G2: [827.6862, 246.2263, 809.6561, 264.2293, 126.033] | H2: [502.4498, 344.2664, 102.5568, 52.0, 20.0] | I2: ['CAEP(d49:6)-1H2O', 'd17:3', 'CAEP(d49:6)-2H2O', 'd17:3+OH', '[C2H8NO3P+H]+'] | J2: 1021.273 | K2: 49.6 | L2: 0.07 | M2: CAEP(d17:3/x:3) | N2: 32 | O2: 1 | P2: y = 0.5302x + -9.5492 | Q2: 0.99231739
A3: 1 | B3: CAEP(d17:3/37:3) | C3: 915.762 | D3: 0.62 | E3: CAEP(d54:6) | F3: 10.07 | G3: [897.7521, 897.7521, 282.2476, 246.2264, 264.2364] | H3: [945.3245, 945.3245, 376.6039, 255.3672, 177.1157] | I3: ['CAEP(d54:6)-1H2O', 'CAEP(d54:6)-1H2O', 'd17:3+2OH', 'd17:3', 'd17:3+OH'] | J3: 2699.7358 | K3: 62 | L3: 1 | M3: CAEP(d17:3/x:3) | N3: 37 | O3: 1 | P3: y = 0.5302x + -9.5492 | Q3: 0.99231739
A4: 1 | B4: CAEP(d17:3/53:3) | C4: 1140.0145 | D4: 0.38 | E4: CAEP(d70:6) | F4: 18.554 | G4: [264.2368, 246.2257, 1014.9765] | H4: [325.3785, 210.3603, 27.0] | I4: ['d17:3+OH', 'd17:3', 'CAEP(d70:6)-C2H8NO3P'] | J4: 562.7388 | K4: 34.2 | L4: 0.94 | M4: CAEP(d17:3/x:3) | N4: 53 | O4: 1 | P4: y = 0.5302x + -9.5492 | Q4: 0.99231739
A5: 2 | B5: Cer(d14:0/18:0) | C5: 512.5034 | D5: 0.83 | E5: Cer(d32:0) | F5: 7.343 | G5: [494.4922, 228.2321, 210.2209, 246.2439, 476.48] | H5: [11305.5947, 4294.0005, 2972.4082, 1127.3517, 606.7742] | I5: ['Cer(d32:0)-1H2O', 'd14:0+OH', 'd14:0', 'd14:0+2OH', 'Cer(d32:0)-2H2O'] | J5: 20306.129 | K5: 83 | L5: 1 | M5: Cer(d14:0/x:0) | N5: 18 | O5: 3 | P5: y = 0.4402x + -0.6004 | Q5: 0.99971138
A6: 3 | B6: Cer(d14:0/20:0) | C6: 540.537 | D6: 0.83 | E6: Cer(d34:0) | F6: 8.181 | G6: [522.5233, 228.2315, 210.2209, 246.2429, 504.5137] | H6: [18996.668, 3852.9404, 2629.9849, 2429.0127, 1796.4441] | I6: ['Cer(d34:0)-1H2O', 'd14:0+OH', 'd14:0', 'd14:0+2OH', 'Cer(d34:0)-2H2O'] | J6: 29705.05 | K6: 83 | L6: 1 | M6: Cer(d14:0/x:0) | N6: 20 | O6: 3 | P6: y = 0.4402x + -0.6004 | Q6: 0.99971138
A7: 2 | B7: Cer(d14:0/22:0) | C7: 568.5662 | D7: 0.83 | E7: Cer(d36:0) | F7: 9.073 | G7: [550.5542, 228.2313, 210.221, 246.2416, 532.5426] | H7: [126174.2109, 34375.543, 21641.6777, 12911.3154, 5821.8608] | I7: ['Cer(d36:0)-1H2O', 'd14:0+OH', 'd14:0', 'd14:0+2OH', 'Cer(d36:0)-2H2O'] | J7: 200924.61 | K7: 83 | L7: 1 | M7: Cer(d14:0/x:0) | N7: 22 | O7: 3 | P7: y = 0.4402x + -0.6004 | Q7: 0.99971138
A8: 2 | B8: Cer(d14:0/23:0) | C8: 582.5824 | D8: 0.83 | E8: Cer(d37:0) | F8: 9.524 | G8: [564.5693, 228.2316, 210.2221, 246.2407, 546.5577] | H8: [16977.707, 3920.9167, 2178.8452, 1274.4218, 1157.8484] | I8: ['Cer(d37:0)-1H2O', 'd14:0+OH', 'd14:0', 'd14:0+2OH', 'Cer(d37:0)-2H2O'] | J8: 25509.739 | K8: 83 | L8: 1 | M8: Cer(d14:0/x:0) | N8: 23 | O8: 3 | P8: y = 0.4402x + -0.6004 | Q8: 0.99971138
A9: 1 | B9: Cer(d14:0/24:0) | C9: 596.5979 | D9: 0.83 | E9: Cer(d38:0) | F9: 9.981 | G9: [578.5864, 228.2302, 560.579, 210.2209, 246.2418] | H9: [12792.3682, 1372.7004, 1322.0033, 1101.8932, 926.7744] | I9: ['Cer(d38:0)-1H2O', 'd14:0+OH', 'Cer(d38:0)-2H2O', 'd14:0', 'd14:0+2OH'] | J9: 17515.739 | K9: 66.4 | L9: 0.82 | M9: Cer(d14:0/x:0) | N9: 24 | O9: 3 | P9: y = 0.4402x + -0.6004 | Q9: 0.99971138
A10: 2 | B10: Cer(d14:1/13:0) | C10: 440.4095 | D10: 0.5 | E10: Cer(d27:1) | F10: 5.301 | G10: [208.2048, 422.4065, 404.3818] | H10: [78.0625, 53.0278, 43.875] | I10: ['d14:1', 'Cer(d27:1)-1H2O', 'Cer(d27:1)-2H2O'] | J10: 174.9653 | K10: 45 | L10: 0.98 | M10: Cer(d14:1/x:0) | N10: 13 | O10: 6 | P10: y = 0.3898x + 0.1170 | Q10: 0.99391314
A11: 2 | B11: Cer(d14:1/16:0) | C11: 482.4564 | D11: 0.67 | E11: Cer(d30:1) | F11: 6.252 | G11: [208.2055, 226.2164, 464.4459, 446.4377] | H11: [51560.2578, 7543.251, 2944.0208, 1089.2339] | I11: ['d14:1', 'd14:1+OH', 'Cer(d30:1)-1H2O', 'Cer(d30:1)-2H2O'] | J11: 63136.764 | K11: 67 | L11: 1 | M11: Cer(d14:1/x:0) | N11: 16 | O11: 6 | P11: y = 0.3898x + 0.1170 | Q11: 0.99391314
A12: 2 | B12: Cer(d14:1/18:0) | C12: 510.4878 | D12: 0.83 | E12: Cer(d32:1) | F12: 7.037 | G12: [208.206, 226.2166, 492.4764, 474.4655, 244.2267] | H12: [17409.2539, 2292.3271, 2244.8577, 725.6166, 46.25] | I12: ['d14:1', 'd14:1+OH', 'Cer(d32:1)-1H2O', 'Cer(d32:1)-2H2O', 'd14:1+2OH'] | J12: 22718.305 | K12: 83 | L12: 1 | M12: Cer(d14:1/x:0) | N12: 18 | O12: 6 | P12: y = 0.3898x + 0.1170 | Q12: 0.99391314
A13: 2 | B13: Cer(d14:1/20:0) | C13: 538.5192 | D13: 0.83 | E13: Cer(d34:1) | F13: 7.888 | G13: [208.2054, 226.216, 520.5071, 502.4967, 244.2263] | H13: [184448.9688, 30581.502, 27351.7383, 6435.5498, 168.625] | I13: ['d14:1', 'd14:1+OH', 'Cer(d34:1)-1H2O', 'Cer(d34:1)-2H2O', 'd14:1+2OH'] | J13: 248986.38 | K13: 83 | L13: 1 | M13: Cer(d14:1/x:0) | N13: 20 | O13: 6 | P13: y = 0.3898x + 0.1170 | Q13: 0.99391314
... A618: 2 | B618: So1P(t23:1) | C618: 466.3293 | D618: 0.43 | E618: So1P(t23:1) | F618: 5.423 | G618: [368.3516, 350.3403, 412.2896] | H618: [175.4, 86.0, 21.0833] | I618: ['So1P(t23:1)-H3PO4', 'So1P(t23:1)-H2O-H3PO4', 'So1P(t23:1)-3H2O'] | J618: 282.4833 | K618: 43 | L618: 1 | M618: So1P(tx:1) | N618: 23 | O618: 388 | P618: y = 0.2505x + -0.3192 | Q618: 0.99888438

Sheet 删除删除片段见重复值与符合保留时间规律重复值后的
A1: 0 | B1: 注释 | C1: target | D1: 匹配度分数 | E1: 1 | F1: RT | G1: 2 | H1: 3 | I1: 4 | J1: 5 | K1: 6 | L1: 7 | M1: 8
A2: 9 | B2: CAEP(d14:2/12:3) | C2: 525.3441 | D2: 0.88 | E2: CAEP(d26:5) | F2: 3.418 | G2: 15024 | H2: [507.3351, 126.0333, 242.2071, 489.3279, 224.1987, 206.1879, 400.3121] | I2: [886.3094, 413.6825, 330.3465, 305.1225, 290.0363, 265.9185, 173.0513] | J2: ['CAEP(d26:5)-1H2O', '[C2H8NO3P+H]+', 'd14:2+2OH', 'CAEP(d26:5)-2H2O', 'd14:2+OH', 'd14:2', 'CAEP(d26:5)-C2H8NO3P'] | K2: 2664.467 | L2: 88 | M2: 1 | N2: #N/A
A3: 16 | B3: CAEP(d14:3/15:0) | C3: 571.4273 | D3: 0.62 | E3: CAEP(d29:3) | F3: 5.283 | G3: 264846 | H3: [553.4244, 222.1835, 204.1763, 535.4133, 240.1936] | I3: [180.0, 145.1635, 116.8929, 81.7788, 64.1607] | J3: ['CAEP(d29:3)-1H2O', 'd14:3+OH', 'd14:3', 'CAEP(d29:3)-2H2O', 'd14:3+2OH'] | K3: 587.9959 | L3: 62 | M3: 1 | N3: #N/A
A4: 37 | B4: CAEP(d14:3/21:3)(2OH) | C4: 665.4654 | D4: 0.75 | E4: CAEP(d35:6)(2OH) | F4: 12.46 | G4: 12180 | H4: [647.4542, 647.4542, 540.4346, 540.4346, 629.4525, 629.4525] | I4: [41.2404, 41.2404, 37.0833, 37.0833, 21.25, 21.25] | J4: ['CAEP(d35:6)(2OH)-1H2O', 'CAEP(d35:6)(2OH)-1H2O', 'CAEP(d35:6)(2OH)-C2H8NO3P', 'CAEP(d35:6)(2OH)-C2H8NO3P', 'CAEP(d35:6)(2OH)-2H2O', 'CAEP(d35:6)(2OH)-2H2O'] | K4: 199.1474 | L4: 75 | M4: 1 | N4: #N/A
A5: 56 | B5: CAEP(d14:3/21:4) | C5: 647.4587 | D5: 0.5 | E5: CAEP(d35:7) | F5: 11.478 | G5: 135914 | H5: [240.1927, 629.4434, 204.1709, 222.1838] | I5: [308.0312, 196.3472, 59.0, 44.0833] | J5: ['d14:3+2OH', 'CAEP(d35:7)-1H2O', 'd14:3', 'd14:3+OH'] | K5: 607.4617 | L5: 40 | M5: 0.59 | N5: #N/A
A6: 97 | B6: CAEP(d14:3/25:4) | C6: 703.5164 | D6: 0.5 | E6: CAEP(d39:7) | F6: 6.942 | G6: 159861 | H6: [685.4972, 204.1732, 240.1965, 667.4903] | I6: [540.1639, 237.2426, 170.4133, 86.125] | J6: ['CAEP(d39:7)-1H2O', 'd14:3', 'd14:3+2OH', 'CAEP(d39:7)-2H2O'] | K6: 1033.9448 | L6: 50 | M6: 1 | N6: #N/A
A7: 10 | B7: CAEP(d14:4/12:1) | C7: 525.3441 | D7: 0.88 | E7: CAEP(d26:5) | F7: 3.418 | G7: 15024 | H7: [507.3351, 126.0333, 202.1594, 489.3279, 220.1698, 238.1808, 400.3121] | I7: [886.3094, 413.6825, 325.0994, 305.1225, 201.9469, 182.656, 173.0513] | J7: ['CAEP(d26:5)-1H2O', '[C2H8NO3P+H]+', 'd14:4', 'CAEP(d26:5)-2H2O', 'd14:4+OH', 'd14:4+2OH', 'CAEP(d26:5)-C2H8NO3P'] | K7: 2487.868 | L7: 70.4 | M7: 0.93 | N7: #N/A
A8: 192 | B8: CAEP(d14:4/40:2) | C8: 915.7619 | D8: 0.5 | E8: CAEP(d54:6) | F8: 10.782 | G8: 40314 | H8: [897.7521, 897.7521, 220.1712, 202.1607] | I8: [945.3245, 945.3245, 641.8412, 160.625] | J8: ['CAEP(d54:6)-1H2O', 'CAEP(d54:6)-1H2O', 'd14:4+OH', 'd14:4'] | K8: 2693.1152 | L8: 50 | M8: 1 | N8: #N/A
A9: 38 | B9: CAEP(d15:3/20:3)(2OH) | C9: 665.4654 | D9: 0.75 | E9: CAEP(d35:6)(2OH) | F9: 12.46 | G9: 12180 | H9: [647.4542, 647.4542, 540.4346, 540.4346, 629.4525, 629.4525] | I9: [41.2404, 41.2404, 37.0833, 37.0833, 21.25, 21.25] | J9: ['CAEP(d35:6)(2OH)-1H2O', 'CAEP(d35:6)(2OH)-1H2O', 'CAEP(d35:6)(2OH)-C2H8NO3P', 'CAEP(d35:6)(2OH)-C2H8NO3P', 'CAEP(d35:6)(2OH)-2H2O', 'CAEP(d35:6)(2OH)-2H2O'] | K9: 199.1474 | L9: 75 | M9: 1 | N9: #N/A
A10: 54 | B10: CAEP(d15:3/20:4) | C10: 647.4586 | D10: 0.38 | E10: CAEP(d35:7) | F10: 15.038 | G10: 84104 | H10: [218.1885, 254.2107, 236.1996] | I10: [230.4444, 49.0625, 26.25] | J10: ['d15:3', 'd15:3+2OH', 'd15:3+OH'] | K10: 305.7569 | L10: 38 | M10: 1 | N10: #N/A
A11: 39 | B11: CAEP(d15:4/20:2)(2OH) | C11: 665.4654 | D11: 0.75 | E11: CAEP(d35:6)(2OH) | F11: 12.46 | G11: 12180 | H11: [647.4542, 647.4542, 540.4346, 540.4346, 629.4525, 629.4525] | I11: [41.2404, 41.2404, 37.0833, 37.0833, 21.25, 21.25] | J11: ['CAEP(d35:6)(2OH)-1H2O', 'CAEP(d35:6)(2OH)-1H2O', 'CAEP(d35:6)(2OH)-C2H8NO3P', 'CAEP(d35:6)(2OH)-C2H8NO3P', 'CAEP(d35:6)(2OH)-2H2O', 'CAEP(d35:6)(2OH)-2H2O'] | K11: 199.1474 | L11: 75 | M11: 1 | N11: #N/A
A12: 24 | B12: CAEP(d16:3/14:0)(2OH) | C12: 601.4384 | D12: 0.38 | E12: CAEP(d30:3)(2OH) | F12: 4.871 | G12: 22393 | H12: [250.2151, 268.2267, 583.4347] | I12: [1137.0951, 267.2656, 133.5956] | J12: ['d16:3+OH', 'd16:3+2OH', 'CAEP(d30:3)(2OH)-1H2O'] | K12: 1537.9563 | L12: 34.2 | M12: 0.82 | N12: #N/A
A13: 41 | B13: CAEP(d17:2/10:4)(2OH) | C13: 553.342 | D13: 0.62 | E13: CAEP(d27:6)(2OH) | F13: 8.117 | G13: 264846 | H13: [266.246, 248.2363, 284.2605, 535.3257, 517.3156] | I13: [4027.4604, 2861.3145, 668.1827, 72.0, 41.5] | J13: ['d17:2+OH', 'd17:2', 'd17:2+2OH', 'CAEP(d27:6)(2OH)-1H2O', 'CAEP(d27:6)(2OH)-2H2O'] | K13: 7670.4576 | L13: 55.8 | M13: 1 | N13: #N/A
... A1759: 94 | B1759: type I B antigen(d30:3/15:4) | C1759: 1677.9436 | D1759: 0.38 | E1759: type I B antigen(d45:7) | F1759: 6.63 | G1759: 108768 | H1759: [1677.9206, 1189.7749, 1351.8056, 1659.9246, 1513.8616, 464.4493, 1497.8731, 1515.8697] | I1759: [36367.4805, 324.8064, 227.1739, 91.1008, 53.0865, 42.05, 40.75, 30.375] | J1759: ['type I B antigen(d45:7)', 'type I B antigen(d45:7)-Gal-Fuc-Gal-H2O', 'type I B antigen(d45:7)-Gal-Fuc-H2O', 'type I B antigen(d45:7)-1H2O', 'type I B antigen(d45:7)-Fuc-H2O', 'd30:3+2OH', 'type I B antigen(d45:7)-Gal-H2O', 'type I B antigen(d45:7)-Gal'] | K1759: 37176.823 | L1759: 38 | M1759: 1 | N1759: #N/A

Sheet 存在保留时间chongfu
A1: 0 | B1: 注释 | C1: target | D1: 匹配度分数 | E1: 1 | F1: RT | G1: 2 | H1: 3 | I1: 4 | J1: 5 | K1: 6 | L1: 7 | M1: 8
A2: 9 | B2: CAEP(d14:2/12:3) | C2: 525.3441 | D2: 0.88 | E2: CAEP(d26:5) | F2: 3.418 | G2: 15024 | H2: [507.3351, 126.0333, 242.2071, 489.3279, 224.1987, 206.1879, 400.3121] | I2: [886.3094, 413.6825, 330.3465, 305.1225, 290.0363, 265.9185, 173.0513] | J2: ['CAEP(d26:5)-1H2O', '[C2H8NO3P+H]+', 'd14:2+2OH', 'CAEP(d26:5)-2H2O', 'd14:2+OH', 'd14:2', 'CAEP(d26:5)-C2H8NO3P'] | K2: 2664.467 | L2: 88 | M2: 1 | N2: #N/A | R2: =VLOOKUP(H2,'[1]算法匹配所有结果汇总(保留时间未归一）'!$H:$O,8,0) -> 5
A3: 16 | B3: CAEP(d14:3/15:0) | C3: 571.4273 | D3: 0.62 | E3: CAEP(d29:3) | F3: 5.283 | G3: 264846 | H3: [553.4244, 222.1835, 204.1763, 535.4133, 240.1936] | I3: [180.0, 145.1635, 116.8929, 81.7788, 64.1607] | J3: ['CAEP(d29:3)-1H2O', 'd14:3+OH', 'd14:3', 'CAEP(d29:3)-2H2O', 'd14:3+2OH'] | K3: 587.9959 | L3: 62 | M3: 1 | N3: #N/A | R3: =VLOOKUP(H3,'[1]算法匹配所有结果汇总(保留时间未归一）'!$H:$O,8,0) -> 4
A4: 37 | B4: CAEP(d14:3/21:3)(2OH) | C4: 665.4654 | D4: 0.75 | E4: CAEP(d35:6)(2OH) | F4: 12.46 | G4: 12180 | H4: [647.4542, 647.4542, 540.4346, 540.4346, 629.4525, 629.4525] | I4: [41.2404, 41.2404, 37.0833, 37.0833, 21.25, 21.25] | J4: ['CAEP(d35:6)(2OH)-1H2O', 'CAEP(d35:6)(2OH)-1H2O', 'CAEP(d35:6)(2OH)-C2H8NO3P', 'CAEP(d35:6)(2OH)-C2H8NO3P', 'CAEP(d35:6)(2OH)-2H2O', 'CAEP(d35:6)(2OH)-2H2O'] | K4: 199.1474 | L4: 75 | M4: 1 | N4: #N/A | R4: =VLOOKUP(H4,'[1]算法匹配所有结果汇总(保留时间未归一）'!$H:$O,8,0) -> 6
A5: 56 | B5: CAEP(d14:3/21:4) | C5: 647.4587 | D5: 0.5 | E5: CAEP(d35:7) | F5: 11.478 | G5: 135914 | H5: [240.1927, 629.4434, 204.1709, 222.1838] | I5: [308.0312, 196.3472, 59.0, 44.0833] | J5: ['d14:3+2OH', 'CAEP(d35:7)-1H2O', 'd14:3', 'd14:3+OH'] | K5: 607.4617 | L5: 40 | M5: 0.59 | N5: #N/A | R5: =VLOOKUP(H5,'[1]算法匹配所有结果汇总(保留时间未归一）'!$H:$O,8,0) -> 1
A6: 97 | B6: CAEP(d14:3/25:4) | C6: 703.5164 | D6: 0.5 | E6: CAEP(d39:7) | F6: 6.942 | G6: 159861 | H6: [685.4972, 204.1732, 240.1965, 667.4903] | I6: [540.1639, 237.2426, 170.4133, 86.125] | J6: ['CAEP(d39:7)-1H2O', 'd14:3', 'd14:3+2OH', 'CAEP(d39:7)-2H2O'] | K6: 1033.9448 | L6: 50 | M6: 1 | N6: #N/A | R6: =VLOOKUP(H6,'[1]算法匹配所有结果汇总(保留时间未归一）'!$H:$O,8,0) -> 2
A7: 10 | B7: CAEP(d14:4/12:1) | C7: 525.3441 | D7: 0.88 | E7: CAEP(d26:5) | F7: 3.418 | G7: 15024 | H7: [507.3351, 126.0333, 202.1594, 489.3279, 220.1698, 238.1808, 400.3121] | I7: [886.3094, 413.6825, 325.0994, 305.1225, 201.9469, 182.656, 173.0513] | J7: ['CAEP(d26:5)-1H2O', '[C2H8NO3P+H]+', 'd14:4', 'CAEP(d26:5)-2H2O', 'd14:4+OH', 'd14:4+2OH', 'CAEP(d26:5)-C2H8NO3P'] | K7: 2487.868 | L7: 70.4 | M7: 0.93 | N7: #N/A | R7: =VLOOKUP(H7,'[1]算法匹配所有结果汇总(保留时间未归一）'!$H:$O,8,0) -> 5
A8: 192 | B8: CAEP(d14:4/40:2) | C8: 915.7619 | D8: 0.5 | E8: CAEP(d54:6) | F8: 10.782 | G8: 40314 | H8: [897.7521, 897.7521, 220.1712, 202.1607] | I8: [945.3245, 945.3245, 641.8412, 160.625] | J8: ['CAEP(d54:6)-1H2O', 'CAEP(d54:6)-1H2O', 'd14:4+OH', 'd14:4'] | K8: 2693.1152 | L8: 50 | M8: 1 | N8: #N/A | R8: =VLOOKUP(H8,'[1]算法匹配所有结果汇总(保留时间未归一）'!$H:$O,8,0) -> 1
A9: 38 | B9: CAEP(d15:3/20:3)(2OH) | C9: 665.4654 | D9: 0.75 | E9: CAEP(d35:6)(2OH) | F9: 12.46 | G9: 12180 | H9: [647.4542, 647.4542, 540.4346, 540.4346, 629.4525, 629.4525] | I9: [41.2404, 41.2404, 37.0833, 37.0833, 21.25, 21.25] | J9: ['CAEP(d35:6)(2OH)-1H2O', 'CAEP(d35:6)(2OH)-1H2O', 'CAEP(d35:6)(2OH)-C2H8NO3P', 'CAEP(d35:6)(2OH)-C2H8NO3P', 'CAEP(d35:6)(2OH)-2H2O', 'CAEP(d35:6)(2OH)-2H2O'] | K9: 199.1474 | L9: 75 | M9: 1 | N9: #N/A | R9: =VLOOKUP(H9,'[1]算法匹配所有结果汇总(保留时间未归一）'!$H:$O,8,0) -> 6
A10: 54 | B10: CAEP(d15:3/20:4) | C10: 647.4586 | D10: 0.38 | E10: CAEP(d35:7) | F10: 15.038 | G10: 84104 | H10: [218.1885, 254.2107, 236.1996] | I10: [230.4444, 49.0625, 26.25] | J10: ['d15:3', 'd15:3+2OH', 'd15:3+OH'] | K10: 305.7569 | L10: 38 | M10: 1 | N10: #N/A | R10: =VLOOKUP(H10,'[1]算法匹配所有结果汇总(保留时间未归一）'!$H:$O,8,0) -> 1
A11: 39 | B11: CAEP(d15:4/20:2)(2OH) | C11: 665.4654 | D11: 0.75 | E11: CAEP(d35:6)(2OH) | F11: 12.46 | G11: 12180 | H11: [647.4542, 647.4542, 540.4346, 540.4346, 629.4525, 629.4525] | I11: [41.2404, 41.2404, 37.0833, 37.0833, 21.25, 21.25] | J11: ['CAEP(d35:6)(2OH)-1H2O', 'CAEP(d35:6)(2OH)-1H2O', 'CAEP(d35:6)(2OH)-C2H8NO3P', 'CAEP(d35:6)(2OH)-C2H8NO3P', 'CAEP(d35:6)(2OH)-2H2O', 'CAEP(d35:6)(2OH)-2H2O'] | K11: 199.1474 | L11: 75 | M11: 1 | N11: #N/A | R11: =VLOOKUP(H11,'[1]算法匹配所有结果汇总(保留时间未归一）'!$H:$O,8,0) -> 6
A12: 24 | B12: CAEP(d16:3/14:0)(2OH) | C12: 601.4384 | D12: 0.38 | E12: CAEP(d30:3)(2OH) | F12: 4.871 | G12: 22393 | H12: [250.2151, 268.2267, 583.4347] | I12: [1137.0951, 267.2656, 133.5956] | J12: ['d16:3+OH', 'd16:3+2OH', 'CAEP(d30:3)(2OH)-1H2O'] | K12: 1537.9563 | L12: 34.2 | M12: 0.82 | N12: #N/A | R12: =VLOOKUP(H12,'[1]算法匹配所有结果汇总(保留时间未归一）'!$H:$O,8,0) -> 4
A13: 41 | B13: CAEP(d17:2/10:4)(2OH) | C13: 553.342 | D13: 0.62 | E13: CAEP(d27:6)(2OH) | F13: 8.117 | G13: 264846 | H13: [266.246, 248.2363, 284.2605, 535.3257, 517.3156] | I13: [4027.4604, 2861.3145, 668.1827, 72.0, 41.5] | J13: ['d17:2+OH', 'd17:2', 'd17:2+2OH', 'CAEP(d27:6)(2OH)-1H2O', 'CAEP(d27:6)(2OH)-2H2O'] | K13: 7670.4576 | L13: 55.8 | M13: 1 | N13: #N/A | R13: =VLOOKUP(H13,'[1]算法匹配所有结果汇总(保留时间未归一）'!$H:$O,8,0) -> 1
... A1654: 94 | B1654: type I B antigen(d30:3/15:4) | C1654: 1677.9436 | D1654: 0.38 | E1654: type I B antigen(d45:7) | F1654: 6.63 | G1654: 108768 | H1654: [1677.9206, 1189.7749, 1351.8056, 1659.9246, 1513.8616, 464.4493, 1497.8731, 1515.8697] | I1654: [36367.4805, 324.8064, 227.1739, 91.1008, 53.0865, 42.05, 40.75, 30.375] | J1654: ['type I B antigen(d45:7)', 'type I B antigen(d45:7)-Gal-Fuc-Gal-H2O', 'type I B antigen(d45:7)-Gal-Fuc-H2O', 'type I B antigen(d45:7)-1H2O', 'type I B antigen(d45:7)-Fuc-H2O', 'd30:3+2OH', 'type I B antigen(d45:7)-Gal-H2O', 'type I B antigen(d45:7)-Gal'] | K1654: 37176.823 | L1654: 38 | M1654: 1 | N1654: #N/A | R1654: =VLOOKUP(H1654,'[1]算法匹配所有结果汇总(保留时间未归一）'!$H:$O,8,0) -> 6
A1655: 5 | B1655: CAEP(d17:3/32:3) | C1655: 845.6922 | D1655: 0.62 | E1655: CAEP(d49:6) | F1655: 8.107 | G1655: [827.6862, 246.2263, 809.6561, 264.2293, 126.033] | H1655: [502.4498, 344.2664, 102.5568, 52.0, 20.0] | I1655: ['CAEP(d49:6)-1H2O', 'd17:3', 'CAEP(d49:6)-2H2O', 'd17:3+OH', '[C2H8NO3P+H]+'] | J1655: 1021.273 | K1655: 49.6 | L1655: 0.07 | M1655: CAEP(d17:3/x:3) | N1655: 32 | O1655: 1 | P1655: y = 0.5302x + -9.5492 | Q1655: 0.99231739 | R1655: =VLOOKUP(G1655,'[1]算法匹配所有结果汇总(保留时间未归一）'!$H:$O,8,0) -> 5
A1656: 1 | B1656: CAEP(d17:3/37:3) | C1656: 915.762 | D1656: 0.62 | E1656: CAEP(d54:6) | F1656: 10.07 | G1656: [897.7521, 897.7521, 282.2476, 246.2264, 264.2364] | H1656: [945.3245, 945.3245, 376.6039, 255.3672, 177.1157] | I1656: ['CAEP(d54:6)-1H2O', 'CAEP(d54:6)-1H2O', 'd17:3+2OH', 'd17:3', 'd17:3+OH'] | J1656: 2699.7358 | K1656: 62 | L1656: 1 | M1656: CAEP(d17:3/x:3) | N1656: 37 | O1656: 1 | P1656: y = 0.5302x + -9.5492 | Q1656: 0.99231739 | R1656: =VLOOKUP(G1656,'[1]算法匹配所有结果汇总(保留时间未归一）'!$H:$O,8,0) -> 1
A1657: 1 | B1657: CAEP(d17:3/53:3) | C1657: 1140.0145 | D1657: 0.38 | E1657: CAEP(d70:6) | F1657: 18.554 | G1657: [264.2368, 246.2257, 1014.9765] | H1657: [325.3785, 210.3603, 27.0] | I1657: ['d17:3+OH', 'd17:3', 'CAEP(d70:6)-C2H8NO3P'] | J1657: 562.7388 | K1657: 34.2 | L1657: 0.94 | M1657: CAEP(d17:3/x:3) | N1657: 53 | O1657: 1 | P1657: y = 0.5302x + -9.5492 | Q1657: 0.99231739 | R1657: =VLOOKUP(G1657,'[1]算法匹配所有结果汇总(保留时间未归一）'!$H:$O,8,0) -> 1
A1658: 2 | B1658: Cer(d14:0/18:0) | C1658: 512.5034 | D1658: 0.83 | E1658: Cer(d32:0) | F1658: 7.343 | G1658: [494.4922, 228.2321, 210.2209, 246.2439, 476.48] | H1658: [11305.5947, 4294.0005, 2972.4082, 1127.3517, 606.7742] | I1658: ['Cer(d32:0)-1H2O', 'd14:0+OH', 'd14:0', 'd14:0+2OH', 'Cer(d32:0)-2H2O'] | J1658: 20306.129 | K1658: 83 | L1658: 1 | M1658: Cer(d14:0/x:0) | N1658: 18 | O1658: 3 | P1658: y = 0.4402x + -0.6004 | Q1658: 0.99971138 | R1658: =VLOOKUP(G1658,'[1]算法匹配所有结果汇总(保留时间未归一）'!$H:$O,8,0) -> 2
A1659: 3 | B1659: Cer(d14:0/20:0) | C1659: 540.537 | D1659: 0.83 | E1659: Cer(d34:0) | F1659: 8.181 | G1659: [522.5233, 228.2315, 210.2209, 246.2429, 504.5137] | H1659: [18996.668, 3852.9404, 2629.9849, 2429.0127, 1796.4441] | I1659: ['Cer(d34:0)-1H2O', 'd14:0+OH', 'd14:0', 'd14:0+2OH', 'Cer(d34:0)-2H2O'] | J1659: 29705.05 | K1659: 83 | L1659: 1 | M1659: Cer(d14:0/x:0) | N1659: 20 | O1659: 3 | P1659: y = 0.4402x + -0.6004 | Q1659: 0.99971138 | R1659: =VLOOKUP(G1659,'[1]算法匹配所有结果汇总(保留时间未归一）'!$H:$O,8,0) -> 3
A1660: 2 | B1660: Cer(d14:0/22:0) | C1660: 568.5662 | D1660: 0.83 | E1660: Cer(d36:0) | F1660: 9.073 | G1660: [550.5542, 228.2313, 210.221, 246.2416, 532.5426] | H1660: [126174.2109, 34375.543, 21641.6777, 12911.3154, 5821.8608] | I1660: ['Cer(d36:0)-1H2O', 'd14:0+OH', 'd14:0', 'd14:0+2OH', 'Cer(d36:0)-2H2O'] | J1660: 200924.61 | K1660: 83 | L1660: 1 | M1660: Cer(d14:0/x:0) | N1660: 22 | O1660: 3 | P1660: y = 0.4402x + -0.6004 | Q1660: 0.99971138 | R1660: =VLOOKUP(G1660,'[1]算法匹配所有结果汇总(保留时间未归一）'!$H:$O,8,0) -> 2
A1661: 2 | B1661: Cer(d14:0/23:0) | C1661: 582.5824 | D1661: 0.83 | E1661: Cer(d37:0) | F1661: 9.524 | G1661: [564.5693, 228.2316, 210.2221, 246.2407, 546.5577] | H1661: [16977.707, 3920.9167, 2178.8452, 1274.4218, 1157.8484] | I1661: ['Cer(d37:0)-1H2O', 'd14:0+OH', 'd14:0', 'd14:0+2OH', 'Cer(d37:0)-2H2O'] | J1661: 25509.739 | K1661: 83 | L1661: 1 | M1661: Cer(d14:0/x:0) | N1661: 23 | O1661: 3 | P1661: y = 0.4402x + -0.6004 | Q1661: 0.99971138 | R1661: =VLOOKUP(G1661,'[1]算法匹配所有结果汇总(保留时间未归一）'!$H:$O,8,0) -> 2
A1662: 1 | B1662: Cer(d14:0/24:0) | C1662: 596.5979 | D1662: 0.83 | E1662: Cer(d38:0) | F1662: 9.981 | G1662: [578.5864, 228.2302, 560.579, 210.2209, 246.2418] | H1662: [12792.3682, 1372.7004, 1322.0033, 1101.8932, 926.7744] | I1662: ['Cer(d38:0)-1H2O', 'd14:0+OH', 'Cer(d38:0)-2H2O', 'd14:0', 'd14:0+2OH'] | J1662: 17515.739 | K1662: 66.4 | L1662: 0.82 | M1662: Cer(d14:0/x:0) | N1662: 24 | O1662: 3 | P1662: y = 0.4402x + -0.6004 | Q1662: 0.99971138 | R1662: =VLOOKUP(G1662,'[1]算法匹配所有结果汇总(保留时间未归一）'!$H:$O,8,0) -> 1
A1663: 2 | B1663: Cer(d14:1/13:0) | C1663: 440.4095 | D1663: 0.5 | E1663: Cer(d27:1) | F1663: 5.301 | G1663: [208.2048, 422.4065, 404.3818] | H1663: [78.0625, 53.0278, 43.875] | I1663: ['d14:1', 'Cer(d27:1)-1H2O', 'Cer(d27:1)-2H2O'] | J1663: 174.9653 | K1663: 45 | L1663: 0.98 | M1663: Cer(d14:1/x:0) | N1663: 13 | O1663: 6 | P1663: y = 0.3898x + 0.1170 | Q1663: 0.99391314 | R1663: =VLOOKUP(G1663,'[1]算法匹配所有结果汇总(保留时间未归一）'!$H:$O,8,0) -> 2
A1664: 2 | B1664: Cer(d14:1/16:0) | C1664: 482.4564 | D1664: 0.67 | E1664: Cer(d30:1) | F1664: 6.252 | G1664: [208.2055, 226.2164, 464.4459, 446.4377] | H1664: [51560.2578, 7543.251, 2944.0208, 1089.2339] | I1664: ['d14:1', 'd14:1+OH', 'Cer(d30:1)-1H2O', 'Cer(d30:1)-2H2O'] | J1664: 63136.764 | K1664: 67 | L1664: 1 | M1664: Cer(d14:1/x:0) | N1664: 16 | O1664: 6 | P1664: y = 0.3898x + 0.1170 | Q1664: 0.99391314 | R1664: =VLOOKUP(G1664,'[1]算法匹配所有结果汇总(保留时间未归一）'!$H:$O,8,0) -> 2
A1665: 2 | B1665: Cer(d14:1/18:0) | C1665: 510.4878 | D1665: 0.83 | E1665: Cer(d32:1) | F1665: 7.037 | G1665: [208.206, 226.2166, 492.4764, 474.4655, 244.2267] | H1665: [17409.2539, 2292.3271, 2244.8577, 725.6166, 46.25] | I1665: ['d14:1', 'd14:1+OH', 'Cer(d32:1)-1H2O', 'Cer(d32:1)-2H2O', 'd14:1+2OH'] | J1665: 22718.305 | K1665: 83 | L1665: 1 | M1665: Cer(d14:1/x:0) | N1665: 18 | O1665: 6 | P1665: y = 0.3898x + 0.1170 | Q1665: 0.99391314 | R1665: =VLOOKUP(G1665,'[1]算法匹配所有结果汇总(保留时间未归一）'!$H:$O,8,0) -> 2
A1666: 2 | B1666: Cer(d14:1/20:0) | C1666: 538.5192 | D1666: 0.83 | E1666: Cer(d34:1) | F1666: 7.888 | G1666: [208.2054, 226.216, 520.5071, 502.4967, 244.2263] | H1666: [184448.9688, 30581.502, 27351.7383, 6435.5498, 168.625] | I1666: ['d14:1', 'd14:1+OH', 'Cer(d34:1)-1H2O', 'Cer(d34:1)-2H2O', 'd14:1+2OH'] | J1666: 248986.38 | K1666: 83 | L1666: 1 | M1666: Cer(d14:1/x:0) | N1666: 20 | O1666: 6 | P1666: y = 0.3898x + 0.1170 | Q1666: 0.99391314 | R1666: =VLOOKUP(G1666,'[1]算法匹配所有结果汇总(保留时间未归一）'!$H:$O,8,0) -> 2
... A2271: 2 | B2271: So1P(t23:1) | C2271: 466.3293 | D2271: 0.43 | E2271: So1P(t23:1) | F2271: 5.423 | G2271: [368.3516, 350.3403, 412.2896] | H2271: [175.4, 86.0, 21.0833] | I2271: ['So1P(t23:1)-H3PO4', 'So1P(t23:1)-H2O-H3PO4', 'So1P(t23:1)-3H2O'] | J2271: 282.4833 | K2271: 43 | L2271: 1 | M2271: So1P(tx:1) | N2271: 23 | O2271: 388 | P2271: y = 0.2505x + -0.3192 | Q2271: 0.99888438 | R2271: =VLOOKUP(G2271,'[1]算法匹配所有结果汇总(保留时间未归一）'!$H:$O,8,0) -> 2

Sheet 原先没有加入的d18系列
B1: 注释 | F1: 未归一化时间 | K1: 强度总和 | O1: 片段位置 | Q1: 归一化时间
A2: 31 | B2: Cer(d18:0/15:0) | C2: 526.5187 | D2: 0.5 | E2: Cer(d33:0) | F2: 10.01 | G2: 36199 | H2: [508.5104, 266.2801, 490.4904] | I2: [128.0476, 81.4706, 24.0833] | J2: ['Cer(d33:0)-1H2O', 'd18:0', 'Cer(d33:0)-2H2O'] | K2: 233.6015 | L2: 45 | M2: 0.94 | O2: =VLOOKUP(I2,'[1]算法匹配所有结果汇总(保留时间未归一）'!$I:$O,7,0) -> 2 | Q2: =F2-2.5 -> 7.51
A3: 4 | B3: Cer(d18:4/15:4) | C3: 510.3949 | D3: 0.5 | E3: Cer(d33:8) | F3: 33.12 | G3: 15024 | H3: [294.2448, 492.3827, 258.2215] | I3: [132.75, 60.1658, 49.3333] | J3: ['d18:4+2OH', 'Cer(d33:8)-1H2O', 'd18:4'] | K3: 242.2491 | L3: 40 | M3: 0.44 | O3: =VLOOKUP(I3,'[1]算法匹配所有结果汇总(保留时间未归一）'!$I:$O,7,0) -> 6 | Q3: =F3-30 -> 3.12
A4: 172 | B4: PGCer(d18:1/35:2) | C4: 954.7875 | D4: 0.5 | E4: PGCer(d53:3) | F4: 15.191 | G4: 212529 | H4: [936.7813, 918.7641, 300.2896, 782.7698, 264.2716] | I4: [97.898, 75.3472, 48.0, 30.875, 28.1607] | J4: ['PGCer(d53:3)-1H2O', 'PGCer(d53:3)-2H2O', 'd18:1+2OH', 'PGCer(d53:3)-phosphoglycerol', 'd18:1'] | K4: 280.2809 | L4: 35 | M4: 0.4 | O4: =VLOOKUP(I4,'[1]算法匹配所有结果汇总(保留时间未归一）'!$I:$O,7,0) -> 1 | Q4: =F4-2 -> 13.191
A5: 188 | B5: PECer(d18:1/34:3) | C5: 907.7633 | D5: 0.44 | E5: PECer(d52:4) | F5: 19.011 | G5: 52108 | H5: [264.2678, 282.275, 889.761, 300.2859] | I5: [181.4083, 95.45, 27.0, 27.0] | J5: ['d18:1', 'd18:1+OH', 'PECer(d52:4)-1H2O', 'd18:1+2OH'] | K5: 330.8583 | L5: 39.6 | M5: 0.49 | O5: =VLOOKUP(I5,'[1]算法匹配所有结果汇总(保留时间未归一）'!$I:$O,7,0) -> 2 | Q5: =F5-2.5 -> 16.511
A6: 17 | B6: PECer(d18:2/11:4)(2OH) | C6: 597.3692 | D6: 0.44 | E6: PECer(d29:6)(2OH) | F6: 17.717 | G6: 8218 | H6: [456.3416, 280.2625, 262.2548, 579.3674] | I6: [169.05, 81.125, 50.45, 42.0833] | J6: ['PECer(d29:6)(2OH)-phosphoethanolamine', 'd18:2+OH', 'd18:2', 'PECer(d29:6)(2OH)-1H2O'] | K6: 342.7083 | L6: 39.6 | M6: 0.57 | O6: =VLOOKUP(I6,'[1]算法匹配所有结果汇总(保留时间未归一）'!$I:$O,7,0) -> 4 | Q6: =F6-12 -> 5.717
A7: 211 | B7: FMC-1(d18:4/35:4) | C7: 994.7703 | D7: 0.36 | E7: FMC-1(d53:8) | F7: 15.625 | G7: 827265 | H7: [294.246, 258.2223, 976.7517, 958.7496] | I7: [165.5156, 101.25, 51.2083, 39.4712] | J7: ['d18:4+2OH', 'd18:4', 'FMC-1(d53:8)-1H2O', 'FMC-1(d53:8)-2H2O'] | K7: 357.4451 | L7: 32.4 | M7: 0.94 | O7: =VLOOKUP(I7,'[1]算法匹配所有结果汇总(保留时间未归一）'!$I:$O,7,0) -> 1 | Q7: =F7-2 -> 13.625
A8: 21 | B8: Cer(d18:2/13:2) | C8: 490.4269 | D8: 0.5 | E8: Cer(d31:4) | F8: 10.891 | G8: 16000 | H8: [280.2595, 298.2747, 262.253] | I8: [129.3472, 124.25, 112.5] | J8: ['d18:2+OH', 'd18:2+2OH', 'd18:2'] | K8: 366.0972 | L8: 45 | M8: 0.89 | O8: =VLOOKUP(I8,'[1]算法匹配所有结果汇总(保留时间未归一）'!$I:$O,7,0) -> 1 | Q8: =F8-2 -> 8.891
A9: 22 | B9: Cer(d18:2/15:3)(2OH) | C9: 532.4397 | D9: 0.5 | E9: Cer(d33:5)(2OH) | F9: 13.432 | G9: 54725 | H9: [280.2617, 298.2727, 496.4188] | I9: [222.4402, 119.2857, 48.0] | J9: ['d18:2+OH', 'd18:2+2OH', 'Cer(d33:5)(2OH)-2H2O'] | K9: 389.7259 | L9: 40 | M9: 0.92 | O9: =VLOOKUP(I9,'[1]算法匹配所有结果汇总(保留时间未归一）'!$I:$O,7,0) -> 3 | Q9: =F9-4.5 -> 8.932
A10: 85 | B10: Cer(d18:3/25:4) | C10: 652.5677 | D10: 0.83 | E10: Cer(d43:7) | F10: 9.711 | G10: 7282 | H10: [296.2638, 634.5617, 260.2413, 616.5468, 278.2506] | I10: [192.0, 121.1111, 74.125, 38.1667, 25.0] | J10: ['d18:3+2OH', 'Cer(d43:7)-1H2O', 'd18:3', 'Cer(d43:7)-2H2O', 'd18:3+OH'] | K10: 450.4028 | L10: 58.1 | M10: 0.34 | O10: =VLOOKUP(I10,'[1]算法匹配所有结果汇总(保留时间未归一）'!$I:$O,7,0) -> 1 | Q10: =F10-2 -> 7.711
A11: 67 | B11: PICer(d18:3/17:4)(2OH) | C11: 798.4498 | D11: 0.44 | E11: PICer(d35:7)(2OH) | F11: 35.556 | G11: 787652 | H11: [296.2593, 278.2489, 636.3911, 780.4313] | I11: [213.4083, 163.025, 58.0, 20.25] | J11: ['d18:3+2OH', 'd18:3+OH', 'PICer(d35:7)(2OH)-C6H10O5', 'PICer(d35:7)(2OH)-1H2O'] | K11: 454.6833 | L11: 35.2 | M11: 0.67 | O11: =VLOOKUP(I11,'[1]算法匹配所有结果汇总(保留时间未归一）'!$I:$O,7,0) -> 6 | Q11: =F11-30 -> 5.556
A12: 172 | B12: FMC-6(d18:4/23:0) | C12: 1018.6854 | D12: 0.36 | E12: FMC-6(d41:4) | F12: 12.51 | G12: 55191 | H12: [294.2408, 958.679, 276.2278, 1000.6794] | I12: [206.875, 112.5, 70.25, 66.0865] | J12: ['d18:4+2OH', 'FMC-6(d41:4)-HOAc', 'd18:4+OH', 'FMC-6(d41:4)-1H2O'] | K12: 455.7115 | L12: 32.4 | M12: 0.03 | O12: =VLOOKUP(I12,'[1]算法匹配所有结果汇总(保留时间未归一）'!$I:$O,7,0) -> 1 | Q12: =F12-2 -> 10.51
A13: 172 | B13: CerP(d18:1/37:1) | C13: 910.8046 | D13: 0.44 | E13: CerP(d55:2) | F13: 12.137 | G13: 36199 | H13: [282.2826, 264.2702, 892.7969, 300.2843] | I13: [186.6421, 175.0, 76.5, 55.0312] | J13: ['d18:1+OH', 'd18:1', 'CerP(d55:2)-1H2O', 'd18:1+2OH'] | K13: 493.1733 | L13: 35.2 | O13: =VLOOKUP(I13,'[1]算法匹配所有结果汇总(保留时间未归一）'!$I:$O,7,0) -> 1 | Q13: =F13-2 -> 10.137
A14: 81 | B14: FMC-2(d18:0/26:2) | C14: 896.7207 | D14: 0.36 | E14: FMC-2(d44:2) | F14: 28.66 | G14: 52108 | H14: [284.2896, 878.722, 266.2843, 656.6697] | I14: [259.2426, 163.0227, 43.0357, 29.25] | J14: ['d18:0+OH', 'FMC-2(d44:2)-1H2O', 'd18:0', 'FMC-2(d44:2)-Gal-H2O-HOAc'] | K14: 494.551 | L14: 28.8 | M14: 0.14 | O14: =VLOOKUP(I14,'[1]算法匹配所有结果汇总(保留时间未归一）'!$I:$O,7,0) -> 4 | Q14: =F14-12 -> 16.66
A15: 80 | B15: FMC-3(d18:0/24:1) | C15: 896.7207 | D15: 0.36 | E15: FMC-3(d42:1) | F15: 28.66 | G15: 52108 | H15: [284.2896, 878.722, 614.6418, 266.2843] | I15: [259.2426, 163.0227, 51.05, 43.0357] | J15: ['d18:0+OH', 'FMC-3(d42:1)-1H2O', 'FMC-3(d42:1)-Gal_OAc-H2O-HOAc', 'd18:0'] | K15: 516.351 | L15: 32.4 | M15: 0.14 | O15: =VLOOKUP(I15,'[1]算法匹配所有结果汇总(保留时间未归一）'!$I:$O,7,0) -> 4 | Q15: =F15-12 -> 16.66
A16: 109 | B16: CAEP(d18:3/17:4)(2OH) | C16: 663.4535 | D16: 0.5 | E16: CAEP(d35:7)(2OH) | F16: 14.343 | G16: 87720 | H16: [296.2603, 260.2407, 538.4331, 278.2489] | I16: [246.375, 159.0833, 87.45, 36.1023] | J16: ['d18:3+2OH', 'd18:3', 'CAEP(d35:7)(2OH)-C2H8NO3P', 'd18:3+OH'] | K16: 529.0106 | L16: 35 | M16: 0.71 | O16: =VLOOKUP(I16,'[1]算法匹配所有结果汇总(保留时间未归一）'!$I:$O,7,0) -> 2 | Q16: =F16-2.5 -> 11.843
A17: 111 | B17: PECer(d18:0/25:2)(2OH) | C17: 801.65 | D17: 0.56 | E17: PECer(d43:2)(2OH) | F17: 15.008 | G17: 69705 | H17: [266.2835, 284.2967, 660.6236, 765.6263, 783.6448] | I17: [277.0179, 162.0, 48.375, 36.0833, 23.0] | J17: ['d18:0', 'd18:0+OH', 'PECer(d43:2)(2OH)-phosphoethanolamine', 'PECer(d43:2)(2OH)-2H2O', 'PECer(d43:2)(2OH)-1H2O'] | K17: 546.4762 | L17: 44.8 | M17: 0.79 | O17: =VLOOKUP(I17,'[1]算法匹配所有结果汇总(保留时间未归一）'!$I:$O,7,0) -> 1 | Q17: =F17-2 -> 13.008
A18: 17 | B18: FMC-3(d18:2/13:0) | C18: 740.5276 | D18: 0.36 | E18: FMC-3(d31:2) | F18: 19.436 | G18: 140163 | H18: [280.2643, 298.2729, 262.255, 476.4562] | I18: [210.75, 198.0, 112.25, 26.5] | J18: ['d18:2+OH', 'd18:2+2OH', 'd18:2', 'FMC-3(d31:2)-Gal_OAc-HOAc'] | K18: 547.5 | L18: 32.4 | M18: 0.99 | O18: =VLOOKUP(I18,'[1]算法匹配所有结果汇总(保留时间未归一）'!$I:$O,7,0) -> 4 | Q18: =F18-12 -> 7.436
A19: 201 | B19: FMC-5(d18:1/16:0) | C19: 910.6227 | D19: 0.36 | E19: FMC-5(d34:1) | F19: 9.487 | G19: 300631 | H19: [282.2764, 264.2653, 874.5926, 850.6086] | I19: [259.225, 177.0312, 74.625, 40.0662] | J19: ['d18:1+OH', 'd18:1', 'FMC-5(d34:1)-2H2O', 'FMC-5(d34:1)-HOAc'] | K19: 550.9474 | L19: 32.4 | M19: 0.91 | O19: =VLOOKUP(I19,'[1]算法匹配所有结果汇总(保留时间未归一）'!$I:$O,7,0) -> 2 | Q19: =F19-2.5 -> 6.987
A20: 137 | B20: Cer(d18:3/30:4) | C20: 722.6443 | D20: 0.5 | E20: Cer(d48:7) | F20: 17.361 | G20: 19952 | H20: [260.2424, 704.6249, 686.6104] | I20: [538.7772, 37.125, 28.0833] | J20: ['d18:3', 'Cer(d48:7)-1H2O', 'Cer(d48:7)-2H2O'] | K20: 603.9855 | L20: 50 | M20: 1 | O20: =VLOOKUP(I20,'[1]算法匹配所有结果汇总(保留时间未归一）'!$I:$O,7,0) -> 1 | Q20: =F20-2 -> 15.361
A21: 20 | B21: N-methylCAEP(d18:1/17:4) | C21: 665.5024 | D21: 0.38 | E21: N-methylCAEP(d35:5) | F21: 42.288 | G21: 143355 | H21: [282.2815, 264.2655, 526.4649] | I21: [437.0477, 129.1667, 41.0833] | J21: ['d18:1+OH', 'd18:1', 'N-methylCAEP(d35:5)-C3H10NO3P'] | K21: 607.2977 | L21: 30.4 | M21: 0.77 | O21: =VLOOKUP(I21,'[1]算法匹配所有结果汇总(保留时间未归一）'!$I:$O,7,0) -> 6 | Q21: =F21-30 -> 12.288
A22: 48 | B22: SM(d18:2/14:0)(2OH) | C22: 689.5227 | D22: 0.36 | E22: SM(d32:2)(2OH) | F22: 16.398 | G22: 56375 | H22: [671.5072, 262.2499, 630.4458, 298.2727] | I22: [256.0321, 169.0536, 135.05, 65.3214] | J22: ['SM(d32:2)(2OH)-1H2O', 'd18:2', 'SM(d32:2)(2OH)-C3H9N', 'd18:2+2OH'] | K22: 625.4571 | L22: 32.4 | M22: 0.88 | O22: =VLOOKUP(I22,'[1]算法匹配所有结果汇总(保留时间未归一）'!$I:$O,7,0) -> 4 | Q22: =F22-12 -> 4.398
A23: 212 | B23: SM(d18:2/31:0)(2OH) | C23: 927.7862 | D23: 0.36 | E23: SM(d49:2)(2OH) | F23: 9.581 | G23: 14584 | H23: [891.7643, 298.2745, 909.7788, 280.2689] | I23: [276.6352, 176.9423, 143.125, 30.375] | J23: ['SM(d49:2)(2OH)-2H2O', 'd18:2+2OH', 'SM(d49:2)(2OH)-1H2O', 'd18:2+OH'] | K23: 627.0775 | L23: 36 | M23: 1 | O23: =VLOOKUP(I23,'[1]算法匹配所有结果汇总(保留时间未归一）'!$I:$O,7,0) -> 2 | Q23: =F23-2.5 -> 7.081
A24: 36 | B24: CerP(d18:2/24:3)(2OH) | C24: 738.5501 | D24: 0.44 | E24: CerP(d42:5)(2OH) | F24: 38.766 | G24: 206949 | H24: [262.2563, 298.277, 280.2631, 640.5747] | I24: [228.1645, 211.1875, 118.0, 99.7788] | J24: ['d18:2', 'd18:2+2OH', 'd18:2+OH', 'CerP(d42:5)(2OH)-H3PO4'] | K24: 657.1308 | L24: 39.6 | M24: 0.49 | O24: =VLOOKUP(I24,'[1]算法匹配所有结果汇总(保留时间未归一）'!$I:$O,7,0) -> 6 | Q24: =F24-30 -> 8.766
A25: 207 | B25: CAEP(d18:4/36:2) | C25: 915.7617 | D25: 0.75 | E25: CAEP(d54:6) | F25: 12.519 | G25: 408755 | H25: [276.2322, 897.7622, 879.7485, 790.7239, 294.248, 258.2221] | I25: [314.0592, 121.0278, 88.875, 75.375, 42.875, 42.375] | J25: ['d18:4+OH', 'CAEP(d54:6)-1H2O', 'CAEP(d54:6)-2H2O', 'CAEP(d54:6)-C2H8NO3P', 'd18:4+2OH', 'd18:4'] | K25: 684.587 | L25: 45 | M25: 0.28 | O25: =VLOOKUP(I25,'[1]算法匹配所有结果汇总(保留时间未归一）'!$I:$O,7,0) -> 2 | Q25: =F25-2.5 -> 10.019
A26: 88 | B26: PGCer(d18:1/13:1) | C26: 648.462 | D26: 0.6 | E26: PGCer(d31:2) | F26: 13.478 | G26: 135914 | H26: [264.2731, 476.4399, 630.4545, 282.2811, 556.4117, 612.4368] | I26: [234.0417, 154.4408, 135.05, 114.0833, 39.5, 25.875] | J26: ['d18:1', 'PGCer(d31:2)-phosphoglycerol', 'PGCer(d31:2)-1H2O', 'd18:1+OH', 'PGCer(d31:2)-C3H8O3', 'PGCer(d31:2)-2H2O'] | K26: 702.9908 | L26: 48 | M26: 0.21 | O26: =VLOOKUP(I26,'[1]算法匹配所有结果汇总(保留时间未归一）'!$I:$O,7,0) -> 1 | Q26: =F26-2 -> 11.478
A27: 183 | B27: CAEP(d18:2/31:2)(2OH) | C27: 865.7154 | D27: 0.62 | E27: CAEP(d49:4)(2OH) | F27: 14.944 | G27: 125980 | H27: [262.2481, 280.2583, 829.685, 847.7033, 298.2705] | I27: [214.245, 196.2474, 125.0625, 116.0, 63.25] | J27: ['d18:2', 'd18:2+OH', 'CAEP(d49:4)(2OH)-2H2O', 'CAEP(d49:4)(2OH)-1H2O', 'd18:2+2OH'] | K27: 714.8049 | L27: 55.8 | M27: 0.84 | O27: =VLOOKUP(I27,'[1]算法匹配所有结果汇总(保留时间未归一）'!$I:$O,7,0) -> 2 | Q27: =F27-2.5 -> 12.444
A28: 180 | B28: FMC-2(d18:3/23:2) | C28: 848.6241 | D28: 0.45 | E28: FMC-2(d41:5) | F28: 14.455 | G28: 223738 | H28: [278.2432, 788.6269, 296.257, 626.563, 260.2371] | I28: [251.0074, 203.0, 169.0083, 76.5, 32.75] | J28: ['d18:3+OH', 'FMC-2(d41:5)-HOAc', 'd18:3+2OH', 'FMC-2(d41:5)-HOAc-Gal', 'd18:3'] | K28: 732.2657 | L28: 36 | M28: 0.65 | O28: =VLOOKUP(I28,'[1]算法匹配所有结果汇总(保留时间未归一）'!$I:$O,7,0) -> 2 | Q28: =F28-2.5 -> 11.955
A29: 178 | B29: FMC-2(d18:4/34:4) | C29: 996.749 | D29: 0.55 | E29: FMC-2(d52:8) | F29: 13.172 | G29: 10209 | H29: [294.2423, 936.7304, 978.7399, 756.6713, 960.7149, 276.2325] | I29: [281.0331, 207.1023, 142.4654, 64.0625, 39.0625, 23.5956] | J29: ['d18:4+2OH', 'FMC-2(d52:8)-HOAc', 'FMC-2(d52:8)-1H2O', 'FMC-2(d52:8)-Gal-H2O-HOAc', 'FMC-2(d52:8)-2H2O', 'd18:4+OH'] | K29: 757.3214 | L29: 38.5 | M29: 0.89 | O29: =VLOOKUP(I29,'[1]算法匹配所有结果汇总(保留时间未归一）'!$I:$O,7,0) -> 1 | Q29: =F29-2 -> 11.172
A30: 57 | B30: Cer(d18:2/26:2)(dOH) | C30: 704.6143 | D30: 0.5 | E30: Cer(d44:4)(dOH) | F30: 22.279 | G30: 125980 | H30: [686.6118, 262.2544, 668.5961] | I30: [384.0855, 320.928, 54.0] | J30: ['Cer(d44:4)(dOH)-1H2O', 'd18:2', 'Cer(d44:4)(dOH)-2H2O'] | K30: 759.0135 | L30: 45 | M30: 0.9 | O30: =VLOOKUP(I30,'[1]算法匹配所有结果汇总(保留时间未归一）'!$I:$O,7,0) -> 4 | Q30: =F30-12 -> 10.279
A31: 37 | B31: Cer(d18:1/20:1)(dOH) | C31: 624.5555 | D31: 0.5 | E31: Cer(d38:2)(dOH) | F31: 20.037 | G31: 95608 | H31: [606.5499, 282.278, 264.2703] | I31: [404.1875, 303.4583, 64.0833] | J31: ['Cer(d38:2)(dOH)-1H2O', 'd18:1+OH', 'd18:1'] | K31: 771.7291 | L31: 45 | M31: 0.91 | O31: =VLOOKUP(I31,'[1]算法匹配所有结果汇总(保留时间未归一）'!$I:$O,7,0) -> 4 | Q31: =F31-12 -> 8.037
A32: 85 | B32: SM(d18:2/25:1) | C32: 825.6838 | D32: 0.36 | E32: SM(d43:3) | F32: 17.283 | G32: 264846 | H32: [104.106, 298.2769, 807.6739, 280.2647] | I32: [292.0947, 286.05, 105.0, 92.654] | J32: ['P-O断裂', 'd18:2+2OH', 'SM(d43:3)-1H2O', 'd18:2+OH'] | K32: 775.7987 | L32: 36 | M32: 1 | O32: =VLOOKUP(I32,'[1]算法匹配所有结果汇总(保留时间未归一）'!$I:$O,7,0) -> 4 | Q32: =F32-12 -> 5.283
A33: 20 | B33: Cer(d18:2/20:3) | C33: 586.5217 | D33: 0.5 | E33: Cer(d38:5) | F33: 20.654 | G33: 827265 | H33: [262.252, 568.5092, 298.2743] | I33: [424.1976, 219.0, 148.4444] | J33: ['d18:2', 'Cer(d38:5)-1H2O', 'd18:2+2OH'] | K33: 791.642 | L33: 45 | M33: 0.56 | O33: =VLOOKUP(I33,'[1]算法匹配所有结果汇总(保留时间未归一）'!$I:$O,7,0) -> 4 | Q33: =F33-12 -> 8.654
A34: 177 | B34: FMC-3(d18:4/32:3) | C34: 996.749 | D34: 0.55 | E34: FMC-3(d50:7) | F34: 13.172 | G34: 10209 | H34: [294.2423, 936.7304, 978.7399, 792.6787, 960.7149, 276.2325] | I34: [281.0331, 207.1023, 142.4654, 99.0, 39.0625, 23.5956] | J34: ['d18:4+2OH', 'FMC-3(d50:7)-HOAc', 'FMC-3(d50:7)-1H2O', 'FMC-3(d50:7)-Gal_OAc', 'FMC-3(d50:7)-2H2O', 'd18:4+OH'] | K34: 792.2589 | L34: 49.5 | M34: 0.93 | O34: =VLOOKUP(I34,'[1]算法匹配所有结果汇总(保留时间未归一）'!$I:$O,7,0) -> 1 | Q34: =F34-2 -> 11.172
A35: 36 | B35: Cer(d18:1/26:2)(dOH) | C35: 706.6366 | D35: 0.5 | E35: Cer(d44:3)(dOH) | F35: 40.346 | G35: 53622 | H35: [688.6306, 282.2788, 264.2706] | I35: [397.1191, 333.9641, 64.0081] | J35: ['Cer(d44:3)(dOH)-1H2O', 'd18:1+OH', 'd18:1'] | K35: 795.0913 | L35: 40 | M35: 0.71 | O35: =VLOOKUP(I35,'[1]算法匹配所有结果汇总(保留时间未归一）'!$I:$O,7,0) -> 6 | Q35: =F35-30 -> 10.346
A36: 76 | B36: CAEP(d18:1/15:0)(2OH) | C36: 647.5108 | D36: 0.5 | E36: CAEP(d33:1)(2OH) | F36: 13.478 | G36: 135914 | H36: [264.2693, 282.2783, 300.2882, 629.5001] | I36: [397.026, 199.5956, 143.0, 73.1111] | J36: ['d18:1', 'd18:1+OH', 'd18:1+2OH', 'CAEP(d33:1)(2OH)-1H2O'] | K36: 812.7327 | L36: 40 | M36: 0.93 | O36: =VLOOKUP(I36,'[1]算法匹配所有结果汇总(保留时间未归一）'!$I:$O,7,0) -> 1 | Q36: =F36-2 -> 11.478
A37: 23 | B37: HexCer(t18:2/12:4)(OH) | C37: 666.421 | D37: 0.36 | E37: HexCer(t30:6)(OH) | F37: 36.892 | G37: 9611 | H37: [260.2407, 278.251, 666.4255, 630.4037] | I37: [337.7723, 305.2041, 138.7961, 38.25] | J37: ['t18:2', 't18:2+OH', 'HexCer(t30:6)(OH)', 'HexCer(t30:6)(OH)-2H2O'] | K37: 820.0225 | L37: 28.8 | M37: 0.05 | O37: =VLOOKUP(I37,'[1]算法匹配所有结果汇总(保留时间未归一）'!$I:$O,7,0) -> 6 | Q37: =F37-30 -> 6.892
A38: 169 | B38: N-methylCAEP(d18:3/33:4) | C38: 885.723 | D38: 0.5 | E38: N-methylCAEP(d51:7) | F38: 15.757 | G38: 180258 | H38: [278.2468, 296.258, 746.6728, 867.7235] | I38: [398.9698, 198.225, 126.651, 124.3603] | J38: ['d18:3+OH', 'd18:3+2OH', 'N-methylCAEP(d51:7)-C3H10NO3P', 'N-methylCAEP(d51:7)-1H2O'] | K38: 848.2061 | L38: 45 | M38: 0.96 | O38: =VLOOKUP(I38,'[1]算法匹配所有结果汇总(保留时间未归一）'!$I:$O,7,0) -> 2 | Q38: =F38-2.5 -> 13.257
A39: 102 | B39: PICer(d18:4/19:2)(2OH) | C39: 828.4992 | D39: 0.56 | E39: PICer(d37:6)(2OH) | F39: 10.15 | G39: 787652 | H39: [810.4875, 294.2419, 792.4649, 666.4372, 568.4628] | I39: [282.3333, 235.0667, 200.3324, 92.5568, 78.2812] | J39: ['PICer(d37:6)(2OH)-1H2O', 'd18:4+2OH', 'PICer(d37:6)(2OH)-2H2O', 'PICer(d37:6)(2OH)-C6H10O5', 'PICer(d37:6)(2OH)-phosphate'] | K39: 888.5704 | L39: 39.2 | M39: 0.87 | O39: =VLOOKUP(I39,'[1]算法匹配所有结果汇总(保留时间未归一）'!$I:$O,7,0) -> 3 | Q39: =F39-4.5 -> 5.65
A40: 56 | B40: HexCer(d18:1/14:0) | C40: 672.5409 | D40: 0.44 | E40: HexCer(d32:1) | F40: 10.139 | G40: 787652 | H40: [672.5404, 300.2905, 654.5343, 264.2668] | I40: [550.8774, 152.025, 128.75, 59.5] | J40: ['HexCer(d32:1)', 'd18:1+2OH', 'HexCer(d32:1)-1H2O', 'd18:1'] | K40: 891.1524 | L40: 35.2 | M40: 0.84 | O40: =VLOOKUP(I40,'[1]算法匹配所有结果汇总(保留时间未归一）'!$I:$O,7,0) -> 3 | Q40: =F40-4.5 -> 5.639
...

Sheet 最终版
B1: 注释 | C1: M+H | E1: 母离子 | F1: 保留时间归一化（二元泵） | G1: 碎片质量 | H1: 碎片强度 | I1: 碎片注释 | J1: 碎片强度总和 | O1: 系列 | P1: 标准曲线
A2: 2 | B2: Cer(d18:1/19:2)(dOH) | C2: 608.5248 | D2: 0.83 | E2: Cer(d37:3)(dOH) | F2: 7.187 | G2: [282.2792, 264.2668, 300.2857, 590.515, 590.515] | H2: [2012.1588, 691.375, 337.9651, 204.3636, 204.3636] | I2: ['d18:1+OH', 'd18:1', 'd18:1+2OH', 'Cer(d37:3)(dOH)-1H2O', 'Cer(d37:3)(dOH)-1H2O'] | J2: 3450.2261 | K2: 74.7 | L2: 0.94 | M2: Cer(d18:1/x:2)(dOH) | N2: 19 | O2: 38 | P2: y = 0.4639x + -1.6129 | Q2: 0.99409646 | S2: 保留时间规律算法问题重新绘制的
A3: 6 | B3: Cer(d18:1/24:2)(dOH) | C3: 678.6007 | D3: 0.67 | E3: Cer(d42:3)(dOH) | F3: 9.512 | G3: [282.2787, 264.2656, 660.5822, 300.2869] | H3: [875.0474, 237.3611, 173.045, 98.1023] | I3: ['d18:1+OH', 'd18:1', 'Cer(d42:3)(dOH)-1H2O', 'd18:1+2OH'] | J3: 1383.5558 | K3: 53.6 | L3: 0.53 | M3: Cer(d18:1/x:2)(dOH) | N3: 24 | O3: 38 | P3: y = 0.4639x + -1.6129 | Q3: 0.99409646
A4: 3 | B4: Cer(d18:1/25:2)(dOH) | C4: 692.616 | D4: 0.83 | E4: Cer(d43:3)(dOH) | F4: 9.928 | G4: [674.6023, 282.2793, 300.2907, 264.2666, 656.6031] | H4: [429.4222, 252.4083, 171.4083, 169.4464, 52.1023] | I4: ['Cer(d43:3)(dOH)-1H2O', 'd18:1+OH', 'd18:1+2OH', 'd18:1', 'Cer(d43:3)(dOH)-2H2O'] | J4: 1074.7875 | K4: 58.1 | L4: 0.37 | M4: Cer(d18:1/x:2)(dOH) | N4: 25 | O4: 38 | P4: y = 0.4639x + -1.6129 | Q4: 0.99409646
A5: 2 | B5: Cer(d18:1/26:2)(dOH) | C5: 706.6318 | D5: 0.83 | E5: Cer(d44:3)(dOH) | F5: 10.358 | G5: [300.2887, 264.2666, 282.2742, 688.6181, 670.5989] | H5: [995.2226, 722.3088, 647.868, 509.1306, 199.8892] | I5: ['d18:1+2OH', 'd18:1', 'd18:1+OH', 'Cer(d44:3)(dOH)-1H2O', 'Cer(d44:3)(dOH)-2H2O'] | J5: 3074.4192 | K5: 83 | L5: 1 | M5: Cer(d18:1/x:2)(dOH) | N5: 26 | O5: 38 | P5: y = 0.4639x + -1.6129 | Q5: 0.99409646
A6: 2 | B6: Cer(t14:0/10:0) | C6: 416.3732 | D6: 0.38 | E6: Cer(t24:0) | F6: 6.308 | G6: [362.3373, 398.3608, 208.2067] | H6: [609.9828, 48.375, 28.125] | I6: ['Cer(t24:0)-3H2O', 'Cer(t24:0)-1H2O', 't14:0'] | J6: 686.4828 | K6: 38 | L6: 1 | M6: Cer(t14:0/x:0) | N6: 10 | O6: 86 | P6: y = 0.4037x + 2.2884 | Q6: 0.99879471
A7: 1 | B7: Cer(t14:0/18:0) | C7: 528.498 | D7: 0.38 | E7: Cer(t32:0) | F7: 9.43 | G7: [208.2018, 510.4791, 226.2184] | H7: [246.175, 194.3707, 20.3472] | I7: ['t14:0', 'Cer(t32:0)-1H2O', 't14:0+OH'] | J7: 460.8929 | K7: 38 | L7: 1 | M7: Cer(t14:0/x:0) | N7: 18 | O7: 86 | P7: y = 0.4037x + 2.2884 | Q7: 0.99879471
A8: 2 | B8: Cer(t14:0/19:0) | C8: 542.5138 | D8: 0.38 | E8: Cer(t33:0) | F8: 9.907 | G8: [208.2029, 226.2141, 262.2375] | H8: [194.1494, 114.0662, 21.0833] | I8: ['t14:0', 't14:0+OH', 't14:0+3OH'] | J8: 329.2989 | K8: 34.2 | L8: 0.84 | M8: Cer(t14:0/x:0) | N8: 19 | O8: 86 | P8: y = 0.4037x + 2.2884 | Q8: 0.99879471
A9: 1 | B9: Cer(t14:0/26:0) | C9: 640.6243 | D9: 0.62 | E9: Cer(t40:0) | F9: 12.774 | G9: [226.2153, 622.6055, 244.2273, 262.2361, 208.2046] | H9: [132.2857, 117.3393, 47.5, 26.3333, 26.125] | I9: ['t14:0+OH', 'Cer(t40:0)-1H2O', 't14:0+2OH', 't14:0+3OH', 't14:0'] | J9: 349.5833 | K9: 62 | L9: 1 | M9: Cer(t14:0/x:0) | N9: 26 | O9: 86 | P9: y = 0.4037x + 2.2884 | Q9: 0.99879471
A10: 2 | B10: Cer(t18:0/14:0) | C10: 528.4993 | D10: 0.38 | E10: Cer(t32:0) | F10: 9.624 | G10: [264.2639, 510.4926, 318.2964] | H10: [212.75, 146.3214, 49.05] | I10: ['t18:0', 'Cer(t32:0)-1H2O', 't18:0+3OH'] | J10: 408.1214 | K10: 34.2 | L10: 0.61 | M10: Cer(t18:0/x:0) | N10: 14 | O10: 133 | P10: y = 0.4079x + 3.8654 | Q10: 0.9940882
A11: 2 | B11: Cer(t18:0/15:0) | C11: 542.5138 | D11: 0.5 | E11: Cer(t33:0) | F11: 9.907 | G11: [264.2643, 300.2882, 318.3029, 282.2816] | H11: [141.4402, 67.0833, 34.25, 25.75] | I11: ['t18:0', 't18:0+2OH', 't18:0+3OH', 't18:0+OH'] | J11: 268.5235 | K11: 40 | L11: 0.68 | M11: Cer(t18:0/x:0) | N11: 15 | O11: 133 | P11: y = 0.4079x + 3.8654 | Q11: 0.9940882
A12: 1 | B12: Cer(t18:0/16:0) | C12: 556.5293 | D12: 0.75 | E12: Cer(t34:0) | F12: 10.404 | G12: [282.2781, 264.2731, 300.2857, 538.5167, 538.5167, 318.3025] | H12: [779.7786, 218.0054, 175.5, 65.25, 65.25, 20.25] | I12: ['t18:0+OH', 't18:0', 't18:0+2OH', 'Cer(t34:0)-1H2O', 'Cer(t34:0)-1H2O', 't18:0+3OH'] | J12: 1324.034 | K12: 75 | L12: 1 | M12: Cer(t18:0/x:0) | N12: 16 | O12: 133 | P12: y = 0.4079x + 3.8654 | Q12: 0.9940882
A13: 5 | B13: Cer(t18:0/16:1)(2OH) | C13: 570.5093 | D13: 0.75 | E13: Cer(t34:1)(2OH) | F13: 5.343 | G13: [552.499, 534.4863, 282.2762, 300.2889, 516.474, 264.2727] | H13: [6793.4268, 1906.8314, 786.9897, 496.5868, 448.6713, 202.0833] | I13: ['Cer(t34:1)(2OH)-1H2O', 'Cer(t34:1)(2OH)-2H2O', 't18:0+OH', 't18:0+2OH', 'Cer(t34:1)(2OH)-3H2O', 't18:0'] | J13: 10634.589 | K13: 67.5 | L13: 0.67 | M13: Cer(t18:0/x:1)(2OH) | N13: 16 | O13: 136 | P13: y = 0.3176x + 0.3953 | Q13: 0.99110375
A14: 2 | B14: Cer(t18:0/18:0) | C14: 584.5609 | D14: 0.38 | E14: Cer(t36:0) | F14: 11.304 | G14: [264.273, 566.5616, 282.2773] | H14: [424.8767, 266.4876, 167.277] | I14: ['t18:0', 'Cer(t36:0)-1H2O', 't18:0+OH'] | J14: 858.6413 | K14: 38 | L14: 1 | M14: Cer(t18:0/x:0) | N14: 18 | O14: 133 | P14: y = 0.4079x + 3.8654 | Q14: 0.9940882
... A580: 2 | B580: So1P(t23:1) | C580: 466.3293 | D580: 0.43 | E580: So1P(t23:1) | F580: 5.423 | G580: [368.3516, 350.3403, 412.2896] | H580: [175.4, 86.0, 21.0833] | I580: ['So1P(t23:1)-H3PO4', 'So1P(t23:1)-H2O-H3PO4', 'So1P(t23:1)-3H2O'] | J580: 282.4833 | K580: 43 | L580: 1 | M580: So1P(tx:1) | N580: 23 | O580: 388 | P580: y = 0.2505x + -0.3192 | Q580: 0.99888438
A581: 1 | B581: Cer(m15:4/11:1) | C581: 402.3362 | D581: 0.5 | E581: Cer(m26:5) | F581: 4.78 | G581: [384.3257, 218.1901] | H581: [8036.3477, 1460.0001] | I581: ['Cer(m26:5)-1H2O', 'm15:4'] | J581: 9496.3478 | K581: 50 | L581: 1 | R581: 不符合线性的保留时间规律的鉴定到的
A582: 2 | B582: Cer(m15:4/31:1) | C582: 682.6498 | D582: 0.5 | E582: Cer(m46:5) | F582: 14.664 | G582: [218.1923, 664.6289] | H582: [677.2669, 148.4714] | I582: ['m15:4', 'Cer(m46:5)-1H2O'] | J582: 825.7383 | K582: 45 | L582: 0.63
A583: 4 | B583: Cer(m20:2/20:4) | C583: 596.5395 | D583: 0.5 | E583: Cer(m40:6) | F583: 8.348 | G583: [310.3071, 578.5185] | H583: [458.9244, 38.0] | I583: ['m20:2+OH', 'Cer(m40:6)-1H2O'] | J583: 496.9244 | K583: 45 | L583: 0.23
A584: 6 | B584: Cer(m20:2/28:4) | C584: 708.6684 | D584: 0.5 | E584: Cer(m48:6) | F584: 14.83 | G584: [310.3111, 292.3007] | H584: [273.281, 269.0] | I584: ['m20:2+OH', 'm20:2'] | J584: 542.281 | K584: 50 | L584: 1
A585: 2 | B585: Cer(t14:0/41:4)(dOH) | C585: 874.7859 | D585: 0.5 | E585: Cer(t55:4)(dOH) | F585: 14.28 | G585: [262.2379, 244.2271, 208.2082, 226.2189] | H585: [5154.4702, 3165.5444, 405.4507, 173.3341] | I585: ['t14:0+3OH', 't14:0+2OH', 't14:0', 't14:0+OH'] | J585: 8898.7994 | K585: 45 | L585: 0.21
A586: 1 | B586: Cer(t14:0/42:4)(dOH) | C586: 888.8008 | D586: 0.38 | E586: Cer(t56:4)(dOH) | F586: 16.284 | G586: [208.2064, 870.7736, 262.2329] | H586: [254.2917, 215.6923, 23.625] | I586: ['t14:0', 'Cer(t56:4)(dOH)-1H2O', 't14:0+3OH'] | J586: 493.609 | K586: 34.2 | L586: 0.81
A587: 3 | B587: Cer(t18:2/16:4)(dOH) | C587: 576.4254 | D587: 0.75 | E587: Cer(t34:6)(dOH) | F587: 5.65 | G587: [296.2577, 314.2708, 278.249, 260.2398, 558.4138, 522.3973] | H587: [1294.0625, 373.6298, 281.6686, 115.4402, 92.125, 58.0865] | I587: ['t18:2+2OH', 't18:2+3OH', 't18:2+OH', 't18:2', 'Cer(t34:6)(dOH)-1H2O', 'Cer(t34:6)(dOH)-3H2O'] | J587: 2215.0126 | K587: 67.5 | L587: 0.39
A588: 2 | B588: Cer(t18:2/38:4)(dOH) | C588: 884.7689 | D588: 0.38 | E588: Cer(t56:6)(dOH) | F588: 14.597 | G588: [278.2467, 866.7611, 830.7358] | H588: [449.375, 143.161, 23.3472] | I588: ['t18:2+OH', 'Cer(t56:6)(dOH)-1H2O', 'Cer(t56:6)(dOH)-3H2O'] | J588: 615.8832 | K588: 38 | L588: 1
A589: 2 | B589: Cer(t21:0/15:0)(2OH) | C589: 600.5558 | D589: 0.62 | E589: Cer(t36:0)(2OH) | F589: 7.832 | G589: [582.5448, 564.5337, 324.3266, 546.5245, 306.3215] | H589: [14663.7061, 3408.5222, 1151.3361, 410.375, 22.25] | I589: ['Cer(t36:0)(2OH)-1H2O', 'Cer(t36:0)(2OH)-2H2O', 't21:0+OH', 'Cer(t36:0)(2OH)-3H2O', 't21:0'] | J589: 19656.189 | K589: 49.6 | L589: 0.62
A590: 2 | B590: Cer(t21:0/18:0)(2OH) | C590: 642.6028 | D590: 0.62 | E590: Cer(t39:0)(2OH) | F590: 11.382 | G590: [342.3323, 624.5876, 306.3151, 606.5719, 360.3455] | H590: [736.6617, 249.845, 211.0179, 32.625, 27.05] | I590: ['t21:0+2OH', 'Cer(t39:0)(2OH)-1H2O', 't21:0', 'Cer(t39:0)(2OH)-2H2O', 't21:0+3OH'] | J590: 1257.1996 | K590: 62 | L590: 1
